Workbook

Sheet Summary
A1: Tick Option Chain Summary
A3: Index | B3: Nearest Expiry | C3: Spot | D3: ATM Strike | E3: ATM Straddle | F3: Status
A4: NIFTY | B4: =NIFTY!B3 -> 46154 | C4: =NIFTY!E3 -> 24104.65 | D4: =NIFTY!B4 -> 24100 | E4: =NIFTY!E4 -> 396.7 | F4: =NIFTY!E5 -> Streaming live ticks for NIFTY 2026-05-12
A5: BANKNIFTY | B5: =BANKNIFTY!B3 -> 46168 | C5: =BANKNIFTY!E3 -> 55059.05 | D5: =BANKNIFTY!B4 -> 55100 | E5: =BANKNIFTY!E4 -> 1974.3 | F5: =BANKNIFTY!E5 -> Streaming live ticks for BANKNIFTY 2026-05-26
A6: SENSEX | B6: =SENSEX!B3 -> 46149 | C6: =SENSEX!E3 -> 77195.56 | D6: =SENSEX!B4 -> 77200 | E6: =SENSEX!E4 -> 679.9 | F6: =SENSEX!E5 -> Streaming live ticks for SENSEX 2026-05-07
A9: Last Updated | B9: 46148.455
A10: Mode | B10: WebSocket tick stream + 300ms batch
A11: Autosave | B11: 60 seconds

Sheet NIFTY
A1: NIFTY Option Chain
A3: Nearest Expiry | B3: 46154 | D3: Spot | E3: 24104.65
A4: ATM Strike | B4: 24100 | D4: ATM Straddle | E4: 396.7
A5: Last Updated | B5: 46148.455 | D5: Status | E5: Streaming live ticks for NIFTY 2026-05-12
A6: Showing ATM +/- 25 strikes
A7: ATM | B7: Strike | C7: Call LTP | D7: Put LTP | E7: Straddle Sum
A8: =IF(B8=$B$4,"ATM","") | B8: 22850 | C8: =IF(RawData!F69="","",RawData!F69) -> 1227.6 | D8: =IF(RawData!F70="","",RawData!F70) -> 4.45 | E8: =IF(OR(C8="",D8=""),"",C8+D8) -> 1232.05
A9: =IF(B9=$B$4,"ATM","") | B9: 22900 | C9: =IF(RawData!F71="","",RawData!F71) -> 1280.8 | D9: =IF(RawData!F72="","",RawData!F72) -> 5.1 | E9: =IF(OR(C9="",D9=""),"",C9+D9) -> 1285.9
A10: =IF(B10=$B$4,"ATM","") | B10: 22950 | C10: =IF(RawData!F73="","",RawData!F73) -> 1110 | D10: =IF(RawData!F74="","",RawData!F74) -> 5.8 | E10: =IF(OR(C10="",D10=""),"",C10+D10) -> 1115.8
A11: =IF(B11=$B$4,"ATM","") | B11: 23000 | C11: =IF(RawData!F75="","",RawData!F75) -> 1151.1 | D11: =IF(RawData!F76="","",RawData!F76) -> 6.55 | E11: =IF(OR(C11="",D11=""),"",C11+D11) -> 1157.65
A12: =IF(B12=$B$4,"ATM","") | B12: 23050 | C12: =IF(RawData!F77="","",RawData!F77) -> 1039.6 | D12: =IF(RawData!F78="","",RawData!F78) -> 7.5 | E12: =IF(OR(C12="",D12=""),"",C12+D12) -> 1047.1
A13: =IF(B13=$B$4,"ATM","") | B13: 23100 | C13: =IF(RawData!F79="","",RawData!F79) -> 1040 | D13: =IF(RawData!F80="","",RawData!F80) -> 8.5 | E13: =IF(OR(C13="",D13=""),"",C13+D13) -> 1048.5
A14: =IF(B14=$B$4,"ATM","") | B14: 23150 | C14: =IF(RawData!F81="","",RawData!F81) -> 1045.85 | D14: =IF(RawData!F82="","",RawData!F82) -> 9.85 | E14: =IF(OR(C14="",D14=""),"",C14+D14) -> 1055.7
A15: =IF(B15=$B$4,"ATM","") | B15: 23200 | C15: =IF(RawData!F83="","",RawData!F83) -> 952 | D15: =IF(RawData!F84="","",RawData!F84) -> 11.45 | E15: =IF(OR(C15="",D15=""),"",C15+D15) -> 963.45
A16: =IF(B16=$B$4,"ATM","") | B16: 23250 | C16: =IF(RawData!F85="","",RawData!F85) -> 960 | D16: =IF(RawData!F86="","",RawData!F86) -> 13.25 | E16: =IF(OR(C16="",D16=""),"",C16+D16) -> 973.25
A17: =IF(B17=$B$4,"ATM","") | B17: 23300 | C17: =IF(RawData!F87="","",RawData!F87) -> 854 | D17: =IF(RawData!F88="","",RawData!F88) -> 15.55 | E17: =IF(OR(C17="",D17=""),"",C17+D17) -> 869.55
A18: =IF(B18=$B$4,"ATM","") | B18: 23350 | C18: =IF(RawData!F89="","",RawData!F89) -> 815.25 | D18: =IF(RawData!F90="","",RawData!F90) -> 18.2 | E18: =IF(OR(C18="",D18=""),"",C18+D18) -> 833.45
A19: =IF(B19=$B$4,"ATM","") | B19: 23400 | C19: =IF(RawData!F91="","",RawData!F91) -> 756 | D19: =IF(RawData!F92="","",RawData!F92) -> 21.35 | E19: =IF(OR(C19="",D19=""),"",C19+D19) -> 777.35
A20: =IF(B20=$B$4,"ATM","") | B20: 23450 | C20: =IF(RawData!F93="","",RawData!F93) -> 742.95 | D20: =IF(RawData!F94="","",RawData!F94) -> 25.1 | E20: =IF(OR(C20="",D20=""),"",C20+D20) -> 768.05
A21: =IF(B21=$B$4,"ATM","") | B21: 23500 | C21: =IF(RawData!F95="","",RawData!F95) -> 672.45 | D21: =IF(RawData!F96="","",RawData!F96) -> 29.55 | E21: =IF(OR(C21="",D21=""),"",C21+D21) -> 702
A22: =IF(B22=$B$4,"ATM","") | B22: 23550 | C22: =IF(RawData!F97="","",RawData!F97) -> 623 | D22: =IF(RawData!F98="","",RawData!F98) -> 34.75 | E22: =IF(OR(C22="",D22=""),"",C22+D22) -> 657.75
A23: =IF(B23=$B$4,"ATM","") | B23: 23600 | C23: =IF(RawData!F99="","",RawData!F99) -> 583.45 | D23: =IF(RawData!F100="","",RawData!F100) -> 40.75 | E23: =IF(OR(C23="",D23=""),"",C23+D23) -> 624.2
A24: =IF(B24=$B$4,"ATM","") | B24: 23650 | C24: =IF(RawData!F101="","",RawData!F101) -> 542.1 | D24: =IF(RawData!F102="","",RawData!F102) -> 47.9 | E24: =IF(OR(C24="",D24=""),"",C24+D24) -> 590
A25: =IF(B25=$B$4,"ATM","") | B25: 23700 | C25: =IF(RawData!F103="","",RawData!F103) -> 497.75 | D25: =IF(RawData!F104="","",RawData!F104) -> 56.1 | E25: =IF(OR(C25="",D25=""),"",C25+D25) -> 553.85
A26: =IF(B26=$B$4,"ATM","") | B26: 23750 | C26: =IF(RawData!F105="","",RawData!F105) -> 456.7 | D26: =IF(RawData!F106="","",RawData!F106) -> 65.8 | E26: =IF(OR(C26="",D26=""),"",C26+D26) -> 522.5
A27: =IF(B27=$B$4,"ATM","") | B27: 23800 | C27: =IF(RawData!F107="","",RawData!F107) -> 417.8 | D27: =IF(RawData!F108="","",RawData!F108) -> 76.45 | E27: =IF(OR(C27="",D27=""),"",C27+D27) -> 494.25
A28: =IF(B28=$B$4,"ATM","") | B28: 23850 | C28: =IF(RawData!F109="","",RawData!F109) -> 380 | D28: =IF(RawData!F110="","",RawData!F110) -> 88.95 | E28: =IF(OR(C28="",D28=""),"",C28+D28) -> 468.95
A29: =IF(B29=$B$4,"ATM","") | B29: 23900 | C29: =IF(RawData!F111="","",RawData!F111) -> 343.75 | D29: =IF(RawData!F112="","",RawData!F112) -> 102.9 | E29: =IF(OR(C29="",D29=""),"",C29+D29) -> 446.65
A30: =IF(B30=$B$4,"ATM","") | B30: 23950 | C30: =IF(RawData!F113="","",RawData!F113) -> 308.8 | D30: =IF(RawData!F114="","",RawData!F114) -> 118.45 | E30: =IF(OR(C30="",D30=""),"",C30+D30) -> 427.25
A31: =IF(B31=$B$4,"ATM","") | B31: 24000 | C31: =IF(RawData!F115="","",RawData!F115) -> 277.35 | D31: =IF(RawData!F116="","",RawData!F116) -> 136.55 | E31: =IF(OR(C31="",D31=""),"",C31+D31) -> 413.9
A32: =IF(B32=$B$4,"ATM","") | B32: 24050 | C32: =IF(RawData!F117="","",RawData!F117) -> 246.85 | D32: =IF(RawData!F118="","",RawData!F118) -> 156.3 | E32: =IF(OR(C32="",D32=""),"",C32+D32) -> 403.15
A33: =IF(B33=$B$4,"ATM","") -> ATM | B33: 24100 | C33: =IF(RawData!F119="","",RawData!F119) -> 219.05 | D33: =IF(RawData!F120="","",RawData!F120) -> 177.65 | E33: =IF(OR(C33="",D33=""),"",C33+D33) -> 396.7
A34: =IF(B34=$B$4,"ATM","") | B34: 24150 | C34: =IF(RawData!F121="","",RawData!F121) -> 192.75 | D34: =IF(RawData!F122="","",RawData!F122) -> 201.35 | E34: =IF(OR(C34="",D34=""),"",C34+D34) -> 394.1
A35: =IF(B35=$B$4,"ATM","") | B35: 24200 | C35: =IF(RawData!F123="","",RawData!F123) -> 168.4 | D35: =IF(RawData!F124="","",RawData!F124) -> 227 | E35: =IF(OR(C35="",D35=""),"",C35+D35) -> 395.4
A36: =IF(B36=$B$4,"ATM","") | B36: 24250 | C36: =IF(RawData!F125="","",RawData!F125) -> 145.95 | D36: =IF(RawData!F126="","",RawData!F126) -> 254.85 | E36: =IF(OR(C36="",D36=""),"",C36+D36) -> 400.8
A37: =IF(B37=$B$4,"ATM","") | B37: 24300 | C37: =IF(RawData!F127="","",RawData!F127) -> 125.75 | D37: =IF(RawData!F128="","",RawData!F128) -> 284.65 | E37: =IF(OR(C37="",D37=""),"",C37+D37) -> 410.4
A38: =IF(B38=$B$4,"ATM","") | B38: 24350 | C38: =IF(RawData!F129="","",RawData!F129) -> 107.45 | D38: =IF(RawData!F130="","",RawData!F130) -> 317 | E38: =IF(OR(C38="",D38=""),"",C38+D38) -> 424.45
A39: =IF(B39=$B$4,"ATM","") | B39: 24400 | C39: =IF(RawData!F131="","",RawData!F131) -> 91.6 | D39: =IF(RawData!F132="","",RawData!F132) -> 349.7 | E39: =IF(OR(C39="",D39=""),"",C39+D39) -> 441.3
A40: =IF(B40=$B$4,"ATM","") | B40: 24450 | C40: =IF(RawData!F133="","",RawData!F133) -> 77.2 | D40: =IF(RawData!F134="","",RawData!F134) -> 383 | E40: =IF(OR(C40="",D40=""),"",C40+D40) -> 460.2
A41: =IF(B41=$B$4,"ATM","") | B41: 24500 | C41: =IF(RawData!F135="","",RawData!F135) -> 64.85 | D41: =IF(RawData!F136="","",RawData!F136) -> 423.3 | E41: =IF(OR(C41="",D41=""),"",C41+D41) -> 488.15
...

Sheet BANKNIFTY
A1: BANKNIFTY Option Chain
A3: Nearest Expiry | B3: 46168 | D3: Spot | E3: 55059.05
A4: ATM Strike | B4: 55100 | D4: ATM Straddle | E4: 1974.3
A5: Last Updated | B5: 46148.455 | D5: Status | E5: Streaming live ticks for BANKNIFTY 2026-05-26
A6: Showing ATM +/- 25 strikes
A7: ATM | B7: Strike | C7: Call LTP | D7: Put LTP | E7: Straddle Sum
A8: =IF(B8=$B$4,"ATM","") | B8: 52600 | C8: =IF(RawData!F376="","",RawData!F376) -> 2600 | D8: =IF(RawData!F377="","",RawData!F377) -> 236.4 | E8: =IF(OR(C8="",D8=""),"",C8+D8) -> 2836.4
A9: =IF(B9=$B$4,"ATM","") | B9: 52700 | C9: =IF(RawData!F378="","",RawData!F378) -> 2850 | D9: =IF(RawData!F379="","",RawData!F379) -> 244.75 | E9: =IF(OR(C9="",D9=""),"",C9+D9) -> 3094.75
A10: =IF(B10=$B$4,"ATM","") | B10: 52800 | C10: =IF(RawData!F380="","",RawData!F380) -> 2561.05 | D10: =IF(RawData!F381="","",RawData!F381) -> 263.85 | E10: =IF(OR(C10="",D10=""),"",C10+D10) -> 2824.9
A11: =IF(B11=$B$4,"ATM","") | B11: 52900 | C11: =IF(RawData!F382="","",RawData!F382) -> 2525 | D11: =IF(RawData!F383="","",RawData!F383) -> 277.75 | E11: =IF(OR(C11="",D11=""),"",C11+D11) -> 2802.75
A12: =IF(B12=$B$4,"ATM","") | B12: 53000 | C12: =IF(RawData!F384="","",RawData!F384) -> 2600 | D12: =IF(RawData!F385="","",RawData!F385) -> 297.4 | E12: =IF(OR(C12="",D12=""),"",C12+D12) -> 2897.4
A13: =IF(B13=$B$4,"ATM","") | B13: 53100 | C13: =IF(RawData!F386="","",RawData!F386) -> 2639.35 | D13: =IF(RawData!F387="","",RawData!F387) -> 310.05 | E13: =IF(OR(C13="",D13=""),"",C13+D13) -> 2949.4
A14: =IF(B14=$B$4,"ATM","") | B14: 53200 | C14: =IF(RawData!F388="","",RawData!F388) -> 2308.85 | D14: =IF(RawData!F389="","",RawData!F389) -> 323.1 | E14: =IF(OR(C14="",D14=""),"",C14+D14) -> 2631.95
A15: =IF(B15=$B$4,"ATM","") | B15: 53300 | C15: =IF(RawData!F390="","",RawData!F390) -> 2408.85 | D15: =IF(RawData!F391="","",RawData!F391) -> 340.45 | E15: =IF(OR(C15="",D15=""),"",C15+D15) -> 2749.3
A16: =IF(B16=$B$4,"ATM","") | B16: 53400 | C16: =IF(RawData!F392="","",RawData!F392) -> 2090.55 | D16: =IF(RawData!F393="","",RawData!F393) -> 365.45 | E16: =IF(OR(C16="",D16=""),"",C16+D16) -> 2456
A17: =IF(B17=$B$4,"ATM","") | B17: 53500 | C17: =IF(RawData!F394="","",RawData!F394) -> 2230 | D17: =IF(RawData!F395="","",RawData!F395) -> 387.6 | E17: =IF(OR(C17="",D17=""),"",C17+D17) -> 2617.6
A18: =IF(B18=$B$4,"ATM","") | B18: 53600 | C18: =IF(RawData!F396="","",RawData!F396) -> 2247.5 | D18: =IF(RawData!F397="","",RawData!F397) -> 407.85 | E18: =IF(OR(C18="",D18=""),"",C18+D18) -> 2655.35
A19: =IF(B19=$B$4,"ATM","") | B19: 53700 | C19: =IF(RawData!F398="","",RawData!F398) -> 2125.4 | D19: =IF(RawData!F399="","",RawData!F399) -> 434.65 | E19: =IF(OR(C19="",D19=""),"",C19+D19) -> 2560.05
A20: =IF(B20=$B$4,"ATM","") | B20: 53800 | C20: =IF(RawData!F400="","",RawData!F400) -> 2013.6 | D20: =IF(RawData!F401="","",RawData!F401) -> 452.3 | E20: =IF(OR(C20="",D20=""),"",C20+D20) -> 2465.9
A21: =IF(B21=$B$4,"ATM","") | B21: 53900 | C21: =IF(RawData!F402="","",RawData!F402) -> 1925 | D21: =IF(RawData!F403="","",RawData!F403) -> 475.95 | E21: =IF(OR(C21="",D21=""),"",C21+D21) -> 2400.95
A22: =IF(B22=$B$4,"ATM","") | B22: 54000 | C22: =IF(RawData!F404="","",RawData!F404) -> 1834.35 | D22: =IF(RawData!F405="","",RawData!F405) -> 505.95 | E22: =IF(OR(C22="",D22=""),"",C22+D22) -> 2340.3
A23: =IF(B23=$B$4,"ATM","") | B23: 54100 | C23: =IF(RawData!F406="","",RawData!F406) -> 1782.55 | D23: =IF(RawData!F407="","",RawData!F407) -> 533.65 | E23: =IF(OR(C23="",D23=""),"",C23+D23) -> 2316.2
A24: =IF(B24=$B$4,"ATM","") | B24: 54200 | C24: =IF(RawData!F408="","",RawData!F408) -> 1746 | D24: =IF(RawData!F409="","",RawData!F409) -> 559.9 | E24: =IF(OR(C24="",D24=""),"",C24+D24) -> 2305.9
A25: =IF(B25=$B$4,"ATM","") | B25: 54300 | C25: =IF(RawData!F410="","",RawData!F410) -> 1684.35 | D25: =IF(RawData!F411="","",RawData!F411) -> 583.2 | E25: =IF(OR(C25="",D25=""),"",C25+D25) -> 2267.55
A26: =IF(B26=$B$4,"ATM","") | B26: 54400 | C26: =IF(RawData!F412="","",RawData!F412) -> 1552.5 | D26: =IF(RawData!F413="","",RawData!F413) -> 616.8 | E26: =IF(OR(C26="",D26=""),"",C26+D26) -> 2169.3
A27: =IF(B27=$B$4,"ATM","") | B27: 54500 | C27: =IF(RawData!F414="","",RawData!F414) -> 1477.1 | D27: =IF(RawData!F415="","",RawData!F415) -> 651.8 | E27: =IF(OR(C27="",D27=""),"",C27+D27) -> 2128.9
A28: =IF(B28=$B$4,"ATM","") | B28: 54600 | C28: =IF(RawData!F416="","",RawData!F416) -> 1409.2 | D28: =IF(RawData!F417="","",RawData!F417) -> 675.9 | E28: =IF(OR(C28="",D28=""),"",C28+D28) -> 2085.1
A29: =IF(B29=$B$4,"ATM","") | B29: 54700 | C29: =IF(RawData!F418="","",RawData!F418) -> 1330.5 | D29: =IF(RawData!F419="","",RawData!F419) -> 720.65 | E29: =IF(OR(C29="",D29=""),"",C29+D29) -> 2051.15
A30: =IF(B30=$B$4,"ATM","") | B30: 54800 | C30: =IF(RawData!F420="","",RawData!F420) -> 1278 | D30: =IF(RawData!F421="","",RawData!F421) -> 759.1 | E30: =IF(OR(C30="",D30=""),"",C30+D30) -> 2037.1
A31: =IF(B31=$B$4,"ATM","") | B31: 54900 | C31: =IF(RawData!F422="","",RawData!F422) -> 1212 | D31: =IF(RawData!F423="","",RawData!F423) -> 799.95 | E31: =IF(OR(C31="",D31=""),"",C31+D31) -> 2011.95
A32: =IF(B32=$B$4,"ATM","") | B32: 55000 | C32: =IF(RawData!F424="","",RawData!F424) -> 1152.6 | D32: =IF(RawData!F425="","",RawData!F425) -> 840 | E32: =IF(OR(C32="",D32=""),"",C32+D32) -> 1992.6
A33: =IF(B33=$B$4,"ATM","") -> ATM | B33: 55100 | C33: =IF(RawData!F426="","",RawData!F426) -> 1095.3 | D33: =IF(RawData!F427="","",RawData!F427) -> 879 | E33: =IF(OR(C33="",D33=""),"",C33+D33) -> 1974.3
A34: =IF(B34=$B$4,"ATM","") | B34: 55200 | C34: =IF(RawData!F428="","",RawData!F428) -> 1040.3 | D34: =IF(RawData!F429="","",RawData!F429) -> 918.55 | E34: =IF(OR(C34="",D34=""),"",C34+D34) -> 1958.85
A35: =IF(B35=$B$4,"ATM","") | B35: 55300 | C35: =IF(RawData!F430="","",RawData!F430) -> 983.9 | D35: =IF(RawData!F431="","",RawData!F431) -> 967.75 | E35: =IF(OR(C35="",D35=""),"",C35+D35) -> 1951.65
A36: =IF(B36=$B$4,"ATM","") | B36: 55400 | C36: =IF(RawData!F432="","",RawData!F432) -> 928.2 | D36: =IF(RawData!F433="","",RawData!F433) -> 1004.55 | E36: =IF(OR(C36="",D36=""),"",C36+D36) -> 1932.75
A37: =IF(B37=$B$4,"ATM","") | B37: 55500 | C37: =IF(RawData!F434="","",RawData!F434) -> 882.15 | D37: =IF(RawData!F435="","",RawData!F435) -> 1059.25 | E37: =IF(OR(C37="",D37=""),"",C37+D37) -> 1941.4
A38: =IF(B38=$B$4,"ATM","") | B38: 55600 | C38: =IF(RawData!F436="","",RawData!F436) -> 831.25 | D38: =IF(RawData!F437="","",RawData!F437) -> 1100.7 | E38: =IF(OR(C38="",D38=""),"",C38+D38) -> 1931.95
A39: =IF(B39=$B$4,"ATM","") | B39: 55700 | C39: =IF(RawData!F438="","",RawData!F438) -> 785.85 | D39: =IF(RawData!F439="","",RawData!F439) -> 1148.25 | E39: =IF(OR(C39="",D39=""),"",C39+D39) -> 1934.1
A40: =IF(B40=$B$4,"ATM","") | B40: 55800 | C40: =IF(RawData!F440="","",RawData!F440) -> 745.75 | D40: =IF(RawData!F441="","",RawData!F441) -> 1206.7 | E40: =IF(OR(C40="",D40=""),"",C40+D40) -> 1952.45
A41: =IF(B41=$B$4,"ATM","") | B41: 55900 | C41: =IF(RawData!F442="","",RawData!F442) -> 695.85 | D41: =IF(RawData!F443="","",RawData!F443) -> 1274.5 | E41: =IF(OR(C41="",D41=""),"",C41+D41) -> 1970.35
...

Sheet SENSEX
A1: SENSEX Option Chain
A3: Nearest Expiry | B3: 46149 | D3: Spot | E3: 77195.56
A4: ATM Strike | B4: 77200 | D4: ATM Straddle | E4: 679.9
A5: Last Updated | B5: 46148.455 | D5: Status | E5: Streaming live ticks for SENSEX 2026-05-07
A6: Showing ATM +/- 25 strikes
A7: ATM | B7: Strike | C7: Call LTP | D7: Put LTP | E7: Straddle Sum
A8: =IF(B8=$B$4,"ATM","") | B8: 74700 | C8: =IF(RawData!F857="","",RawData!F857) | D8: =IF(RawData!F858="","",RawData!F858) -> 3.45 | E8: =IF(OR(C8="",D8=""),"",C8+D8)
A9: =IF(B9=$B$4,"ATM","") | B9: 74800 | C9: =IF(RawData!F859="","",RawData!F859) | D9: =IF(RawData!F860="","",RawData!F860) -> 3.75 | E9: =IF(OR(C9="",D9=""),"",C9+D9)
A10: =IF(B10=$B$4,"ATM","") | B10: 74900 | C10: =IF(RawData!F861="","",RawData!F861) | D10: =IF(RawData!F862="","",RawData!F862) -> 4.25 | E10: =IF(OR(C10="",D10=""),"",C10+D10)
A11: =IF(B11=$B$4,"ATM","") | B11: 75000 | C11: =IF(RawData!F863="","",RawData!F863) -> 2314.4 | D11: =IF(RawData!F864="","",RawData!F864) -> 4.95 | E11: =IF(OR(C11="",D11=""),"",C11+D11) -> 2319.35
A12: =IF(B12=$B$4,"ATM","") | B12: 75100 | C12: =IF(RawData!F865="","",RawData!F865) -> 1955.15 | D12: =IF(RawData!F866="","",RawData!F866) -> 5.55 | E12: =IF(OR(C12="",D12=""),"",C12+D12) -> 1960.7
A13: =IF(B13=$B$4,"ATM","") | B13: 75200 | C13: =IF(RawData!F867="","",RawData!F867) -> 2193.15 | D13: =IF(RawData!F868="","",RawData!F868) -> 6.3 | E13: =IF(OR(C13="",D13=""),"",C13+D13) -> 2199.45
A14: =IF(B14=$B$4,"ATM","") | B14: 75300 | C14: =IF(RawData!F869="","",RawData!F869) -> 1850 | D14: =IF(RawData!F870="","",RawData!F870) -> 7.4 | E14: =IF(OR(C14="",D14=""),"",C14+D14) -> 1857.4
A15: =IF(B15=$B$4,"ATM","") | B15: 75400 | C15: =IF(RawData!F871="","",RawData!F871) -> 1758.55 | D15: =IF(RawData!F872="","",RawData!F872) -> 8.85 | E15: =IF(OR(C15="",D15=""),"",C15+D15) -> 1767.4
A16: =IF(B16=$B$4,"ATM","") | B16: 75500 | C16: =IF(RawData!F873="","",RawData!F873) -> 1820 | D16: =IF(RawData!F874="","",RawData!F874) -> 10.7 | E16: =IF(OR(C16="",D16=""),"",C16+D16) -> 1830.7
A17: =IF(B17=$B$4,"ATM","") | B17: 75600 | C17: =IF(RawData!F875="","",RawData!F875) -> 1556.95 | D17: =IF(RawData!F876="","",RawData!F876) -> 13.4 | E17: =IF(OR(C17="",D17=""),"",C17+D17) -> 1570.35
A18: =IF(B18=$B$4,"ATM","") | B18: 75700 | C18: =IF(RawData!F877="","",RawData!F877) -> 1643.7 | D18: =IF(RawData!F878="","",RawData!F878) -> 16.35 | E18: =IF(OR(C18="",D18=""),"",C18+D18) -> 1660.05
A19: =IF(B19=$B$4,"ATM","") | B19: 75800 | C19: =IF(RawData!F879="","",RawData!F879) -> 1546.55 | D19: =IF(RawData!F880="","",RawData!F880) -> 20.2 | E19: =IF(OR(C19="",D19=""),"",C19+D19) -> 1566.75
A20: =IF(B20=$B$4,"ATM","") | B20: 75900 | C20: =IF(RawData!F881="","",RawData!F881) -> 1436.4 | D20: =IF(RawData!F882="","",RawData!F882) -> 25.05 | E20: =IF(OR(C20="",D20=""),"",C20+D20) -> 1461.45
A21: =IF(B21=$B$4,"ATM","") | B21: 76000 | C21: =IF(RawData!F883="","",RawData!F883) -> 1328.05 | D21: =IF(RawData!F884="","",RawData!F884) -> 30.6 | E21: =IF(OR(C21="",D21=""),"",C21+D21) -> 1358.65
A22: =IF(B22=$B$4,"ATM","") | B22: 76100 | C22: =IF(RawData!F885="","",RawData!F885) -> 1245.65 | D22: =IF(RawData!F886="","",RawData!F886) -> 38.05 | E22: =IF(OR(C22="",D22=""),"",C22+D22) -> 1283.7
A23: =IF(B23=$B$4,"ATM","") | B23: 76200 | C23: =IF(RawData!F887="","",RawData!F887) -> 1150 | D23: =IF(RawData!F888="","",RawData!F888) -> 46.8 | E23: =IF(OR(C23="",D23=""),"",C23+D23) -> 1196.8
A24: =IF(B24=$B$4,"ATM","") | B24: 76300 | C24: =IF(RawData!F889="","",RawData!F889) -> 1048.75 | D24: =IF(RawData!F890="","",RawData!F890) -> 57.35 | E24: =IF(OR(C24="",D24=""),"",C24+D24) -> 1106.1
A25: =IF(B25=$B$4,"ATM","") | B25: 76400 | C25: =IF(RawData!F891="","",RawData!F891) -> 973.85 | D25: =IF(RawData!F892="","",RawData!F892) -> 69.95 | E25: =IF(OR(C25="",D25=""),"",C25+D25) -> 1043.8
A26: =IF(B26=$B$4,"ATM","") | B26: 76500 | C26: =IF(RawData!F893="","",RawData!F893) -> 877.75 | D26: =IF(RawData!F894="","",RawData!F894) -> 85.35 | E26: =IF(OR(C26="",D26=""),"",C26+D26) -> 963.1
A27: =IF(B27=$B$4,"ATM","") | B27: 76600 | C27: =IF(RawData!F895="","",RawData!F895) -> 804.8 | D27: =IF(RawData!F896="","",RawData!F896) -> 103.4 | E27: =IF(OR(C27="",D27=""),"",C27+D27) -> 908.2
A28: =IF(B28=$B$4,"ATM","") | B28: 76700 | C28: =IF(RawData!F897="","",RawData!F897) -> 717.65 | D28: =IF(RawData!F898="","",RawData!F898) -> 124.9 | E28: =IF(OR(C28="",D28=""),"",C28+D28) -> 842.55
A29: =IF(B29=$B$4,"ATM","") | B29: 76800 | C29: =IF(RawData!F899="","",RawData!F899) -> 643.6 | D29: =IF(RawData!F900="","",RawData!F900) -> 149.5 | E29: =IF(OR(C29="",D29=""),"",C29+D29) -> 793.1
A30: =IF(B30=$B$4,"ATM","") | B30: 76900 | C30: =IF(RawData!F901="","",RawData!F901) -> 571.3 | D30: =IF(RawData!F902="","",RawData!F902) -> 178.75 | E30: =IF(OR(C30="",D30=""),"",C30+D30) -> 750.05
A31: =IF(B31=$B$4,"ATM","") | B31: 77000 | C31: =IF(RawData!F903="","",RawData!F903) -> 505 | D31: =IF(RawData!F904="","",RawData!F904) -> 212.7 | E31: =IF(OR(C31="",D31=""),"",C31+D31) -> 717.7
A32: =IF(B32=$B$4,"ATM","") | B32: 77100 | C32: =IF(RawData!F905="","",RawData!F905) -> 442.35 | D32: =IF(RawData!F906="","",RawData!F906) -> 250.05 | E32: =IF(OR(C32="",D32=""),"",C32+D32) -> 692.4
A33: =IF(B33=$B$4,"ATM","") -> ATM | B33: 77200 | C33: =IF(RawData!F907="","",RawData!F907) -> 386.85 | D33: =IF(RawData!F908="","",RawData!F908) -> 293.05 | E33: =IF(OR(C33="",D33=""),"",C33+D33) -> 679.9
A34: =IF(B34=$B$4,"ATM","") | B34: 77300 | C34: =IF(RawData!F909="","",RawData!F909) -> 336.05 | D34: =IF(RawData!F910="","",RawData!F910) -> 343.4 | E34: =IF(OR(C34="",D34=""),"",C34+D34) -> 679.45
A35: =IF(B35=$B$4,"ATM","") | B35: 77400 | C35: =IF(RawData!F911="","",RawData!F911) -> 289.25 | D35: =IF(RawData!F912="","",RawData!F912) -> 395.8 | E35: =IF(OR(C35="",D35=""),"",C35+D35) -> 685.05
A36: =IF(B36=$B$4,"ATM","") | B36: 77500 | C36: =IF(RawData!F913="","",RawData!F913) -> 247.5 | D36: =IF(RawData!F914="","",RawData!F914) -> 454.55 | E36: =IF(OR(C36="",D36=""),"",C36+D36) -> 702.05
A37: =IF(B37=$B$4,"ATM","") | B37: 77600 | C37: =IF(RawData!F915="","",RawData!F915) -> 211.15 | D37: =IF(RawData!F916="","",RawData!F916) -> 516.7 | E37: =IF(OR(C37="",D37=""),"",C37+D37) -> 727.85
A38: =IF(B38=$B$4,"ATM","") | B38: 77700 | C38: =IF(RawData!F917="","",RawData!F917) -> 180.35 | D38: =IF(RawData!F918="","",RawData!F918) -> 588 | E38: =IF(OR(C38="",D38=""),"",C38+D38) -> 768.35
A39: =IF(B39=$B$4,"ATM","") | B39: 77800 | C39: =IF(RawData!F919="","",RawData!F919) -> 152.5 | D39: =IF(RawData!F920="","",RawData!F920) -> 660.7 | E39: =IF(OR(C39="",D39=""),"",C39+D39) -> 813.2
A40: =IF(B40=$B$4,"ATM","") | B40: 77900 | C40: =IF(RawData!F921="","",RawData!F921) -> 129.35 | D40: =IF(RawData!F922="","",RawData!F922) -> 732 | E40: =IF(OR(C40="",D40=""),"",C40+D40) -> 861.35
A41: =IF(B41=$B$4,"ATM","") | B41: 78000 | C41: =IF(RawData!F923="","",RawData!F923) -> 109.5 | D41: =IF(RawData!F924="","",RawData!F924) -> 814.85 | E41: =IF(OR(C41="",D41=""),"",C41+D41) -> 924.35
...

Sheet RawData
A2: NIFTY | B2: 46154 | C2: NSE:NIFTY 50 | F2: 24104.65 | K2: 24171 | L2: 24250.85 | M2: 24091.15 | N2: 24032.8
A3: NIFTY | B3: 46154 | C3: NIFTY2651221200CE | D3: 21200 | E3: CE | F3: 2069.95 | G3: 0 | H3: 0 | I3: 0 | J3: 0 | K3: 0 | L3: 0 | M3: 0 | N3: 2069.95 | O3: 2880 | P3: 25569.229
A4: NIFTY | B4: 46154 | C4: NIFTY2651221200PE | D4: 21200 | E4: PE | F4: 1.05 | G4: 3173430 | H4: 3797560 | I4: 3813810 | J4: 3384680 | K4: 1.5 | L4: 1.6 | M4: 0.95 | N4: 1.5 | O4: 1 | P4: 46148.455
A5: NIFTY | B5: 46154 | C5: NIFTY2651221250CE | D5: 21250 | E5: CE | F5: 2022.35 | G5: 0 | H5: 0 | I5: 0 | J5: 0 | K5: 0 | L5: 0 | M5: 0 | N5: 2022.35 | O5: 2683.95 | P5: 25569.229
A6: NIFTY | B6: 46154 | C6: NIFTY2651221250PE | D6: 21250 | E6: PE | F6: 1.05 | G6: 250120 | H6: 127855 | I6: 127855 | J6: 19240 | K6: 1.65 | L6: 1.65 | M6: 1.05 | N6: 1.65 | O6: 1 | P6: 46148.455
A7: NIFTY | B7: 46154 | C7: NIFTY2651221300CE | D7: 21300 | E7: CE | F7: 1974.9 | G7: 0 | H7: 0 | I7: 0 | J7: 0 | K7: 0 | L7: 0 | M7: 0 | N7: 1974.9 | O7: 2653.85 | P7: 25569.229
A8: NIFTY | B8: 46154 | C8: NIFTY2651221300PE | D8: 21300 | E8: PE | F8: 1.2 | G8: 287495 | H8: 444405 | I8: 444405 | J8: 396045 | K8: 1.55 | L8: 1.6 | M8: 1.15 | N8: 1.65 | O8: 1.15 | P8: 46148.454
A9: NIFTY | B9: 46154 | C9: NIFTY2651221350CE | D9: 21350 | E9: CE | F9: 1927.7 | G9: 0 | H9: 0 | I9: 0 | J9: 0 | K9: 0 | L9: 0 | M9: 0 | N9: 1927.7 | O9: 2590.65 | P9: 25569.229
A10: NIFTY | B10: 46154 | C10: NIFTY2651221350PE | D10: 21350 | E10: PE | F10: 1.15 | G10: 72930 | H10: 32890 | I10: 39910 | J10: 8125 | K10: 1.85 | L10: 1.85 | M10: 1.15 | N10: 1.7 | O10: 1.15 | P10: 46148.455
A11: NIFTY | B11: 46154 | C11: NIFTY2651221400CE | D11: 21400 | E11: CE | F11: 2653.25 | G11: 0 | H11: 65 | I11: 65 | J11: 65 | K11: 0 | L11: 0 | M11: 0 | N11: 2653.25 | O11: 2547.2 | P11: 46147.639
A12: NIFTY | B12: 46154 | C12: NIFTY2651221400PE | D12: 21400 | E12: PE | F12: 1.25 | G12: 231270 | H12: 64610 | I12: 75140 | J12: 30745 | K12: 1.6 | L12: 1.85 | M12: 1.15 | N12: 1.75 | O12: 1.25 | P12: 46148.455
A13: NIFTY | B13: 46154 | C13: NIFTY2651221450CE | D13: 21450 | E13: CE | F13: 1834.05 | G13: 0 | H13: 0 | I13: 0 | J13: 0 | K13: 0 | L13: 0 | M13: 0 | N13: 1834.05 | O13: 2511.2 | P13: 25569.229
A14: NIFTY | B14: 46154 | C14: NIFTY2651221450PE | D14: 21450 | E14: PE | F14: 1.25 | G14: 213200 | H14: 58955 | I14: 77350 | J14: 12155 | K14: 2.3 | L14: 2.35 | M14: 1.25 | N14: 1.8 | O14: 1.25 | P14: 46148.455
... A218: NIFTY | B218: 46154 | C218: NIFTY2651226550PE | D218: 26550 | E218: PE | F218: 2380 | G218: 0 | H218: 65 | I218: 65 | J218: 65 | K218: 0 | L218: 0 | M218: 0 | N218: 2380 | O218: 2307.85 | P218: 46146.511
A219: BANKNIFTY | B219: 46168 | C219: NSE:NIFTY BANK | F219: 55059.05 | K219: 55113.4 | L219: 55344.95 | M219: 55007.55 | N219: 54547.05
A220: BANKNIFTY | B220: 46168 | C220: BANKNIFTY26MAY43000CE | D220: 43000 | E220: CE | F220: 8000 | G220: 0 | H220: 30 | I220: 30 | J220: 30 | K220: 0 | L220: 0 | M220: 0 | N220: 8000 | O220: 11848.4 | P220: 46114.398
A221: BANKNIFTY | B221: 46168 | C221: BANKNIFTY26MAY43000PE | D221: 43000 | E221: PE | F221: 5.45 | G221: 25980 | H221: 94110 | I221: 94230 | J221: 88050 | K221: 5.95 | L221: 7.2 | M221: 5.05 | N221: 6.6 | O221: 5.35 | P221: 46148.455
A222: BANKNIFTY | B222: 46168 | C222: BANKNIFTY26MAY43500CE | D222: 43500 | E222: CE | F222: 18263.65 | G222: 0 | H222: 0 | I222: 0 | J222: 0 | K222: 0 | L222: 0 | M222: 0 | N222: 18263.65 | O222: 10465.1 | P222: 25569.229
A223: BANKNIFTY | B223: 46168 | C223: BANKNIFTY26MAY43500PE | D223: 43500 | E223: PE | F223: 5.4 | G223: 2700 | H223: 20310 | I223: 20370 | J223: 20310 | K223: 5.35 | L223: 6.45 | M223: 5.35 | N223: 6.65 | O223: 5.35 | P223: 46148.451
A224: BANKNIFTY | B224: 46168 | C224: BANKNIFTY26MAY44000CE | D224: 44000 | E224: CE | F224: 12162 | G224: 0 | H224: 1290 | I224: 1290 | J224: 1290 | K224: 0 | L224: 0 | M224: 0 | N224: 12162 | O224: 10189.6 | P224: 46141.436
A225: BANKNIFTY | B225: 46168 | C225: BANKNIFTY26MAY44000PE | D225: 44000 | E225: PE | F225: 6.1 | G225: 10290 | H225: 91950 | I225: 91950 | J225: 89880 | K225: 7.1 | L225: 7.2 | M225: 6.05 | N225: 7.8 | O225: 6.05 | P225: 46148.451
A226: BANKNIFTY | B226: 46168 | C226: BANKNIFTY26MAY44500CE | D226: 44500 | E226: CE | F226: 17280.1 | G226: 0 | H226: 0 | I226: 0 | J226: 0 | K226: 0 | L226: 0 | M226: 0 | N226: 17280.1 | O226: 9637.15 | P226: 25569.229
A227: BANKNIFTY | B227: 46168 | C227: BANKNIFTY26MAY44500PE | D227: 44500 | E227: PE | F227: 6.6 | G227: 5880 | H227: 6720 | I227: 6780 | J227: 6420 | K227: 7.75 | L227: 7.8 | M227: 6.1 | N227: 7.85 | O227: 6.6 | P227: 46148.449
A228: BANKNIFTY | B228: 46168 | C228: BANKNIFTY26MAY45000CE | D228: 45000 | E228: CE | F228: 16788.35 | G228: 0 | H228: 0 | I228: 0 | J228: 0 | K228: 0 | L228: 0 | M228: 0 | N228: 16788.35 | O228: 9500.8 | P228: 25569.229
A229: BANKNIFTY | B229: 46168 | C229: BANKNIFTY26MAY45000PE | D229: 45000 | E229: PE | F229: 7 | G229: 14070 | H229: 104820 | I229: 105900 | J229: 104820 | K229: 8.25 | L229: 8.4 | M229: 6.8 | N229: 8.75 | O229: 6.75 | P229: 46148.453
A230: BANKNIFTY | B230: 46168 | C230: BANKNIFTY26MAY45300CE | D230: 45300 | E230: CE | F230: 15239 | G230: 0 | H230: 0 | I230: 0 | J230: 0 | K230: 0 | L230: 0 | M230: 0 | N230: 15239 | O230: 8921.05 | P230: 25569.229
A231: BANKNIFTY | B231: 46168 | C231: BANKNIFTY26MAY45300PE | D231: 45300 | E231: PE | F231: 8.7 | G231: 870 | H231: 3060 | I231: 3060 | J231: 3000 | K231: 9 | L231: 9 | M231: 7.3 | N231: 9.9 | O231: 7.4 | P231: 46148.453
... A659: BANKNIFTY | B659: 46168 | C659: BANKNIFTY26MAY68500PE | D659: 68500 | E659: PE | F659: 10900 | G659: 0 | H659: 150 | I659: 150 | J659: 150 | K659: 0 | L659: 0 | M659: 0 | N659: 10900 | O659: 11578.75 | P659: 46134.438
F660: 77195.56 | K660: 77424.36 | L660: 77675.01 | M660: 77153.3 | N660: 77017.79
F662: 0.4 | G662: 15660 | H662: 20180 | I662: 21220 | J662: 12020 | K662: 0.35 | L662: 0.55 | M662: 0.35 | N662: 0.6 | O662: 0.4 | P662: 46148.449
F664: 0.4 | G664: 16140 | H664: 36680 | I664: 37800 | J664: 33560 | K664: 0.35 | L664: 0.6 | M664: 0.35 | N664: 0.6 | O664: 0.4 | P664: 46148.455
F670: 0.5 | G670: 120 | H670: 1800 | I670: 1840 | J670: 1800 | K670: 0.8 | L670: 1 | M670: 0.5 | N670: 1.25 | O670: 0.4 | P670: 46148.451
F672: 0.3 | G672: 260 | H672: 840 | I672: 1060 | J672: 840 | K672: 0.45 | L672: 0.45 | M672: 0.3 | N672: 0.55 | O672: 0.25 | P672: 46148.451
F682: 0.5 | G682: 1640 | H682: 5960 | I682: 6720 | J682: 5960 | K682: 0.45 | L682: 0.55 | M682: 0.45 | N682: 0.35 | O682: 0.4 | P682: 46148.45
F684: 0.5 | G684: 2140 | H684: 2360 | I684: 2400 | J684: 2360 | K684: 0.4 | L684: 0.6 | M684: 0.25 | N684: 0.6 | O684: 0.3 | P684: 46148.45
F686: 0.45 | G686: 540 | H686: 980 | I686: 1520 | J686: 980 | K686: 0.45 | L686: 0.45 | M686: 0.45 | N686: 0.55 | O686: 0.5 | P686: 46148.412
F692: 0.3 | G692: 120 | H692: 860 | I692: 860 | J692: 860 | K692: 0.3 | L692: 0.3 | M692: 0.3 | N692: 0.55 | O692: 0.3 | P692: 46148.439
F694: 0.55 | G694: 2300 | H694: 2760 | I694: 2880 | J694: 840 | K694: 0.8 | L694: 0.8 | M694: 0.5 | N694: 0.65 | O694: 0.5 | P694: 46148.454
F698: 0.6 | G698: 20 | H698: 1080 | I698: 1080 | J698: 1080 | K698: 0.6 | L698: 0.6 | M698: 0.6 | N698: 0.55 | O698: 0.3 | P698: 46148.455
F704: 0.4 | G704: 2580 | H704: 3740 | I704: 4180 | J704: 3740 | K704: 0.6 | L704: 0.6 | M704: 0.3 | N704: 0.55 | O704: 0.4 | P704: 46148.452
...

Sheet Meta
A1: simple-option-chain-v4
