Workbook

Sheet Summary
A1: Tick Option Chain Summary
A3: Index | B3: Nearest Expiry | C3: Spot | D3: ATM Strike | E3: ATM Straddle | F3: Status
A4: NIFTY | B4: =NIFTY!B3 -> 46147 | C4: =NIFTY!E3 -> 24028.05 | D4: =NIFTY!B4 -> 24050 | E4: =NIFTY!E4 -> 58.95 | F4: =NIFTY!E5 -> Streaming live ticks for NIFTY 2026-05-05
A5: BANKNIFTY | B5: =BANKNIFTY!B3 -> 46168 | C5: =BANKNIFTY!E3 -> 54727.1 | D5: =BANKNIFTY!B4 -> 54700 | E5: =BANKNIFTY!E4 -> 2126.9 | F5: =BANKNIFTY!E5 -> Streaming live ticks for BANKNIFTY 2026-05-26
A6: SENSEX | B6: =SENSEX!B3 -> 46149 | C6: =SENSEX!E3 -> 76984.91 | D6: =SENSEX!B4 -> 77000 | E6: =SENSEX!E4 -> 887.45 | F6: =SENSEX!E5 -> Streaming live ticks for SENSEX 2026-05-07
A9: Last Updated | B9: 46147.587
A10: Mode | B10: WebSocket tick stream + 300ms batch
A11: Autosave | B11: 60 seconds

Sheet NIFTY
A1: NIFTY Option Chain
A3: Nearest Expiry | B3: 46147 | D3: Spot | E3: 24028.05
A4: ATM Strike | B4: 24050 | D4: ATM Straddle | E4: 58.95
A5: Last Updated | B5: 46147.587 | D5: Status | E5: Streaming live ticks for NIFTY 2026-05-05
A7: ATM | B7: Strike | C7: Call LTP | D7: Put LTP | E7: Straddle Sum
A8: =IF(B8=$B$4,"ATM","") | B8: 20100 | C8: =IF(RawData!J3="","",RawData!J3) -> 2979.95 | D8: =IF(RawData!J4="","",RawData!J4) -> 0.1 | E8: =IF(OR(C8="",D8=""),"",C8+D8) -> 2980.05
A9: =IF(B9=$B$4,"ATM","") | B9: 20150 | C9: =IF(RawData!J5="","",RawData!J5) -> 2930.7 | D9: =IF(RawData!J6="","",RawData!J6) -> 0.1 | E9: =IF(OR(C9="",D9=""),"",C9+D9) -> 2930.8
A10: =IF(B10=$B$4,"ATM","") | B10: 20200 | C10: =IF(RawData!J7="","",RawData!J7) -> 2881.5 | D10: =IF(RawData!J8="","",RawData!J8) -> 0.05 | E10: =IF(OR(C10="",D10=""),"",C10+D10) -> 2881.55
A11: =IF(B11=$B$4,"ATM","") | B11: 20250 | C11: =IF(RawData!J9="","",RawData!J9) -> 2832.3 | D11: =IF(RawData!J10="","",RawData!J10) -> 0.1 | E11: =IF(OR(C11="",D11=""),"",C11+D11) -> 2832.4
A12: =IF(B12=$B$4,"ATM","") | B12: 20300 | C12: =IF(RawData!J11="","",RawData!J11) -> 2783.2 | D12: =IF(RawData!J12="","",RawData!J12) -> 0.05 | E12: =IF(OR(C12="",D12=""),"",C12+D12) -> 2783.25
A13: =IF(B13=$B$4,"ATM","") | B13: 20350 | C13: =IF(RawData!J13="","",RawData!J13) -> 2734.15 | D13: =IF(RawData!J14="","",RawData!J14) -> 0.1 | E13: =IF(OR(C13="",D13=""),"",C13+D13) -> 2734.25
A14: =IF(B14=$B$4,"ATM","") | B14: 20400 | C14: =IF(RawData!J15="","",RawData!J15) -> 2685.15 | D14: =IF(RawData!J16="","",RawData!J16) -> 0.1 | E14: =IF(OR(C14="",D14=""),"",C14+D14) -> 2685.25
A15: =IF(B15=$B$4,"ATM","") | B15: 20450 | C15: =IF(RawData!J17="","",RawData!J17) -> 2636.25 | D15: =IF(RawData!J18="","",RawData!J18) -> 0.05 | E15: =IF(OR(C15="",D15=""),"",C15+D15) -> 2636.3
A16: =IF(B16=$B$4,"ATM","") | B16: 20500 | C16: =IF(RawData!J19="","",RawData!J19) -> 2587.4 | D16: =IF(RawData!J20="","",RawData!J20) -> 0.1 | E16: =IF(OR(C16="",D16=""),"",C16+D16) -> 2587.5
A17: =IF(B17=$B$4,"ATM","") | B17: 20550 | C17: =IF(RawData!J21="","",RawData!J21) -> 3533.1 | D17: =IF(RawData!J22="","",RawData!J22) -> 0.15 | E17: =IF(OR(C17="",D17=""),"",C17+D17) -> 3533.25
A18: =IF(B18=$B$4,"ATM","") | B18: 20600 | C18: =IF(RawData!J23="","",RawData!J23) -> 3483.65 | D18: =IF(RawData!J24="","",RawData!J24) -> 0.1 | E18: =IF(OR(C18="",D18=""),"",C18+D18) -> 3483.75
A19: =IF(B19=$B$4,"ATM","") | B19: 20650 | C19: =IF(RawData!J25="","",RawData!J25) -> 3332.65 | D19: =IF(RawData!J26="","",RawData!J26) -> 0.15 | E19: =IF(OR(C19="",D19=""),"",C19+D19) -> 3332.8
A20: =IF(B20=$B$4,"ATM","") | B20: 20700 | C20: =IF(RawData!J27="","",RawData!J27) -> 2393.05 | D20: =IF(RawData!J28="","",RawData!J28) -> 0.1 | E20: =IF(OR(C20="",D20=""),"",C20+D20) -> 2393.15
A21: =IF(B21=$B$4,"ATM","") | B21: 20750 | C21: =IF(RawData!J29="","",RawData!J29) -> 2344.75 | D21: =IF(RawData!J30="","",RawData!J30) -> 0.15 | E21: =IF(OR(C21="",D21=""),"",C21+D21) -> 2344.9
A22: =IF(B22=$B$4,"ATM","") | B22: 20800 | C22: =IF(RawData!J31="","",RawData!J31) -> 2296.6 | D22: =IF(RawData!J32="","",RawData!J32) -> 0.05 | E22: =IF(OR(C22="",D22=""),"",C22+D22) -> 2296.65
A23: =IF(B23=$B$4,"ATM","") | B23: 20850 | C23: =IF(RawData!J33="","",RawData!J33) -> 3236.25 | D23: =IF(RawData!J34="","",RawData!J34) -> 0.1 | E23: =IF(OR(C23="",D23=""),"",C23+D23) -> 3236.35
A24: =IF(B24=$B$4,"ATM","") | B24: 20900 | C24: =IF(RawData!J35="","",RawData!J35) -> 3144.9 | D24: =IF(RawData!J36="","",RawData!J36) -> 0.1 | E24: =IF(OR(C24="",D24=""),"",C24+D24) -> 3145
A25: =IF(B25=$B$4,"ATM","") | B25: 20950 | C25: =IF(RawData!J37="","",RawData!J37) -> 2153 | D25: =IF(RawData!J38="","",RawData!J38) -> 0.2 | E25: =IF(OR(C25="",D25=""),"",C25+D25) -> 2153.2
A26: =IF(B26=$B$4,"ATM","") | B26: 21000 | C26: =IF(RawData!J39="","",RawData!J39) -> 2989.4 | D26: =IF(RawData!J40="","",RawData!J40) -> 0.05 | E26: =IF(OR(C26="",D26=""),"",C26+D26) -> 2989.45
A27: =IF(B27=$B$4,"ATM","") | B27: 21050 | C27: =IF(RawData!J41="","",RawData!J41) -> 3056.95 | D27: =IF(RawData!J42="","",RawData!J42) -> 0.05 | E27: =IF(OR(C27="",D27=""),"",C27+D27) -> 3057
A28: =IF(B28=$B$4,"ATM","") | B28: 21100 | C28: =IF(RawData!J43="","",RawData!J43) -> 2876.7 | D28: =IF(RawData!J44="","",RawData!J44) -> 0.1 | E28: =IF(OR(C28="",D28=""),"",C28+D28) -> 2876.8
A29: =IF(B29=$B$4,"ATM","") | B29: 21150 | C29: =IF(RawData!J45="","",RawData!J45) -> 2869.15 | D29: =IF(RawData!J46="","",RawData!J46) -> 0.05 | E29: =IF(OR(C29="",D29=""),"",C29+D29) -> 2869.2
A30: =IF(B30=$B$4,"ATM","") | B30: 21200 | C30: =IF(RawData!J47="","",RawData!J47) -> 2939.8 | D30: =IF(RawData!J48="","",RawData!J48) -> 0.05 | E30: =IF(OR(C30="",D30=""),"",C30+D30) -> 2939.85
A31: =IF(B31=$B$4,"ATM","") | B31: 21250 | C31: =IF(RawData!J49="","",RawData!J49) -> 2840.3 | D31: =IF(RawData!J50="","",RawData!J50) -> 0.1 | E31: =IF(OR(C31="",D31=""),"",C31+D31) -> 2840.4
A32: =IF(B32=$B$4,"ATM","") | B32: 21300 | C32: =IF(RawData!J51="","",RawData!J51) -> 2780.05 | D32: =IF(RawData!J52="","",RawData!J52) -> 0.05 | E32: =IF(OR(C32="",D32=""),"",C32+D32) -> 2780.1
A33: =IF(B33=$B$4,"ATM","") | B33: 21350 | C33: =IF(RawData!J53="","",RawData!J53) -> 1779.5 | D33: =IF(RawData!J54="","",RawData!J54) -> 0.1 | E33: =IF(OR(C33="",D33=""),"",C33+D33) -> 1779.6
A34: =IF(B34=$B$4,"ATM","") | B34: 21400 | C34: =IF(RawData!J55="","",RawData!J55) -> 2578.7 | D34: =IF(RawData!J56="","",RawData!J56) -> 0.05 | E34: =IF(OR(C34="",D34=""),"",C34+D34) -> 2578.75
A35: =IF(B35=$B$4,"ATM","") | B35: 21450 | C35: =IF(RawData!J57="","",RawData!J57) -> 2455.75 | D35: =IF(RawData!J58="","",RawData!J58) -> 0.2 | E35: =IF(OR(C35="",D35=""),"",C35+D35) -> 2455.95
A36: =IF(B36=$B$4,"ATM","") | B36: 21500 | C36: =IF(RawData!J59="","",RawData!J59) -> 2450 | D36: =IF(RawData!J60="","",RawData!J60) -> 0.1 | E36: =IF(OR(C36="",D36=""),"",C36+D36) -> 2450.1
A37: =IF(B37=$B$4,"ATM","") | B37: 21550 | C37: =IF(RawData!J61="","",RawData!J61) -> 1599.75 | D37: =IF(RawData!J62="","",RawData!J62) -> 0.1 | E37: =IF(OR(C37="",D37=""),"",C37+D37) -> 1599.85
A38: =IF(B38=$B$4,"ATM","") | B38: 21600 | C38: =IF(RawData!J63="","",RawData!J63) -> 1555.7 | D38: =IF(RawData!J64="","",RawData!J64) -> 0.05 | E38: =IF(OR(C38="",D38=""),"",C38+D38) -> 1555.75
A39: =IF(B39=$B$4,"ATM","") | B39: 21650 | C39: =IF(RawData!J65="","",RawData!J65) -> 1512.1 | D39: =IF(RawData!J66="","",RawData!J66) -> 0.05 | E39: =IF(OR(C39="",D39=""),"",C39+D39) -> 1512.15
A40: =IF(B40=$B$4,"ATM","") | B40: 21700 | C40: =IF(RawData!J67="","",RawData!J67) -> 1468.9 | D40: =IF(RawData!J68="","",RawData!J68) -> 0.1 | E40: =IF(OR(C40="",D40=""),"",C40+D40) -> 1469
A41: =IF(B41=$B$4,"ATM","") | B41: 21750 | C41: =IF(RawData!J69="","",RawData!J69) -> 1426.2 | D41: =IF(RawData!J70="","",RawData!J70) -> 0.05 | E41: =IF(OR(C41="",D41=""),"",C41+D41) -> 1426.25
A42: =IF(B42=$B$4,"ATM","") | B42: 21800 | C42: =IF(RawData!J71="","",RawData!J71) -> 1383.9 | D42: =IF(RawData!J72="","",RawData!J72) -> 0.05 | E42: =IF(OR(C42="",D42=""),"",C42+D42) -> 1383.95
...

Sheet BANKNIFTY
A1: BANKNIFTY Option Chain
A3: Nearest Expiry | B3: 46168 | D3: Spot | E3: 54727.1
A4: ATM Strike | B4: 54700 | D4: ATM Straddle | E4: 2126.9
A5: Last Updated | B5: 46147.587 | D5: Status | E5: Streaming live ticks for BANKNIFTY 2026-05-26
A7: ATM | B7: Strike | C7: Call LTP | D7: Put LTP | E7: Straddle Sum
A8: =IF(B8=$B$4,"ATM","") | B8: 43000 | C8: =IF(RawData!J264="","",RawData!J264) -> 8000 | D8: =IF(RawData!J265="","",RawData!J265) -> 7.05 | E8: =IF(OR(C8="",D8=""),"",C8+D8) -> 8007.05
A9: =IF(B9=$B$4,"ATM","") | B9: 43500 | C9: =IF(RawData!J266="","",RawData!J266) -> 18263.65 | D9: =IF(RawData!J267="","",RawData!J267) -> 6.8 | E9: =IF(OR(C9="",D9=""),"",C9+D9) -> 18270.45
A10: =IF(B10=$B$4,"ATM","") | B10: 44000 | C10: =IF(RawData!J268="","",RawData!J268) -> 12162 | D10: =IF(RawData!J269="","",RawData!J269) -> 7.65 | E10: =IF(OR(C10="",D10=""),"",C10+D10) -> 12169.65
A11: =IF(B11=$B$4,"ATM","") | B11: 44500 | C11: =IF(RawData!J270="","",RawData!J270) -> 17280.1 | D11: =IF(RawData!J271="","",RawData!J271) -> 8.3 | E11: =IF(OR(C11="",D11=""),"",C11+D11) -> 17288.4
A12: =IF(B12=$B$4,"ATM","") | B12: 45000 | C12: =IF(RawData!J272="","",RawData!J272) -> 16788.35 | D12: =IF(RawData!J273="","",RawData!J273) -> 8.75 | E12: =IF(OR(C12="",D12=""),"",C12+D12) -> 16797.1
A13: =IF(B13=$B$4,"ATM","") | B13: 45300 | C13: =IF(RawData!J274="","",RawData!J274) -> 15239 | D13: =IF(RawData!J275="","",RawData!J275) -> 11.05 | E13: =IF(OR(C13="",D13=""),"",C13+D13) -> 15250.05
A14: =IF(B14=$B$4,"ATM","") | B14: 45400 | C14: =IF(RawData!J276="","",RawData!J276) -> 15140.55 | D14: =IF(RawData!J277="","",RawData!J277) -> 12.75 | E14: =IF(OR(C14="",D14=""),"",C14+D14) -> 15153.3
A15: =IF(B15=$B$4,"ATM","") | B15: 45500 | C15: =IF(RawData!J278="","",RawData!J278) -> 16296.6 | D15: =IF(RawData!J279="","",RawData!J279) -> 11.3 | E15: =IF(OR(C15="",D15=""),"",C15+D15) -> 16307.9
A16: =IF(B16=$B$4,"ATM","") | B16: 45600 | C16: =IF(RawData!J280="","",RawData!J280) -> 15647.5 | D16: =IF(RawData!J281="","",RawData!J281) -> 13.2 | E16: =IF(OR(C16="",D16=""),"",C16+D16) -> 15660.7
A17: =IF(B17=$B$4,"ATM","") | B17: 45700 | C17: =IF(RawData!J282="","",RawData!J282) -> 15549.05 | D17: =IF(RawData!J283="","",RawData!J283) -> 10.5 | E17: =IF(OR(C17="",D17=""),"",C17+D17) -> 15559.55
A18: =IF(B18=$B$4,"ATM","") | B18: 45800 | C18: =IF(RawData!J284="","",RawData!J284) -> 15450.65 | D18: =IF(RawData!J285="","",RawData!J285) -> 11.15 | E18: =IF(OR(C18="",D18=""),"",C18+D18) -> 15461.8
A19: =IF(B19=$B$4,"ATM","") | B19: 45900 | C19: =IF(RawData!J286="","",RawData!J286) -> 15352.25 | D19: =IF(RawData!J287="","",RawData!J287) -> 12.35 | E19: =IF(OR(C19="",D19=""),"",C19+D19) -> 15364.6
A20: =IF(B20=$B$4,"ATM","") | B20: 46000 | C20: =IF(RawData!J288="","",RawData!J288) -> 9080.75 | D20: =IF(RawData!J289="","",RawData!J289) -> 12.7 | E20: =IF(OR(C20="",D20=""),"",C20+D20) -> 9093.45
A21: =IF(B21=$B$4,"ATM","") | B21: 46100 | C21: =IF(RawData!J290="","",RawData!J290) -> 15706.55 | D21: =IF(RawData!J291="","",RawData!J291) -> 13.65 | E21: =IF(OR(C21="",D21=""),"",C21+D21) -> 15720.2
A22: =IF(B22=$B$4,"ATM","") | B22: 46200 | C22: =IF(RawData!J292="","",RawData!J292) -> 15608.2 | D22: =IF(RawData!J293="","",RawData!J293) -> 13 | E22: =IF(OR(C22="",D22=""),"",C22+D22) -> 15621.2
A23: =IF(B23=$B$4,"ATM","") | B23: 46300 | C23: =IF(RawData!J294="","",RawData!J294) -> 15509.85 | D23: =IF(RawData!J295="","",RawData!J295) -> 13.05 | E23: =IF(OR(C23="",D23=""),"",C23+D23) -> 15522.9
A24: =IF(B24=$B$4,"ATM","") | B24: 46400 | C24: =IF(RawData!J296="","",RawData!J296) -> 15411.5 | D24: =IF(RawData!J297="","",RawData!J297) -> 14.1 | E24: =IF(OR(C24="",D24=""),"",C24+D24) -> 15425.6
A25: =IF(B25=$B$4,"ATM","") | B25: 46500 | C25: =IF(RawData!J298="","",RawData!J298) -> 10600 | D25: =IF(RawData!J299="","",RawData!J299) -> 15 | E25: =IF(OR(C25="",D25=""),"",C25+D25) -> 10615
A26: =IF(B26=$B$4,"ATM","") | B26: 46600 | C26: =IF(RawData!J300="","",RawData!J300) -> 15214.8 | D26: =IF(RawData!J301="","",RawData!J301) -> 15.35 | E26: =IF(OR(C26="",D26=""),"",C26+D26) -> 15230.15
A27: =IF(B27=$B$4,"ATM","") | B27: 46700 | C27: =IF(RawData!J302="","",RawData!J302) -> 15116.5 | D27: =IF(RawData!J303="","",RawData!J303) -> 20.55 | E27: =IF(OR(C27="",D27=""),"",C27+D27) -> 15137.05
A28: =IF(B28=$B$4,"ATM","") | B28: 46800 | C28: =IF(RawData!J304="","",RawData!J304) -> 15018.15 | D28: =IF(RawData!J305="","",RawData!J305) -> 20.65 | E28: =IF(OR(C28="",D28=""),"",C28+D28) -> 15038.8
A29: =IF(B29=$B$4,"ATM","") | B29: 46900 | C29: =IF(RawData!J306="","",RawData!J306) -> 14919.8 | D29: =IF(RawData!J307="","",RawData!J307) -> 20.4 | E29: =IF(OR(C29="",D29=""),"",C29+D29) -> 14940.2
A30: =IF(B30=$B$4,"ATM","") | B30: 47000 | C30: =IF(RawData!J308="","",RawData!J308) -> 7707.45 | D30: =IF(RawData!J309="","",RawData!J309) -> 18.4 | E30: =IF(OR(C30="",D30=""),"",C30+D30) -> 7725.85
A31: =IF(B31=$B$4,"ATM","") | B31: 47100 | C31: =IF(RawData!J310="","",RawData!J310) -> 14723.15 | D31: =IF(RawData!J311="","",RawData!J311) -> 20 | E31: =IF(OR(C31="",D31=""),"",C31+D31) -> 14743.15
A32: =IF(B32=$B$4,"ATM","") | B32: 47200 | C32: =IF(RawData!J312="","",RawData!J312) -> 14624.85 | D32: =IF(RawData!J313="","",RawData!J313) -> 0.25 | E32: =IF(OR(C32="",D32=""),"",C32+D32) -> 14625.1
A33: =IF(B33=$B$4,"ATM","") | B33: 47300 | C33: =IF(RawData!J314="","",RawData!J314) -> 14526.5 | D33: =IF(RawData!J315="","",RawData!J315) -> 0.3 | E33: =IF(OR(C33="",D33=""),"",C33+D33) -> 14526.8
A34: =IF(B34=$B$4,"ATM","") | B34: 47400 | C34: =IF(RawData!J316="","",RawData!J316) -> 14428.2 | D34: =IF(RawData!J317="","",RawData!J317) -> 0.35 | E34: =IF(OR(C34="",D34=""),"",C34+D34) -> 14428.55
A35: =IF(B35=$B$4,"ATM","") | B35: 47500 | C35: =IF(RawData!J318="","",RawData!J318) -> 9500 | D35: =IF(RawData!J319="","",RawData!J319) -> 22.85 | E35: =IF(OR(C35="",D35=""),"",C35+D35) -> 9522.85
A36: =IF(B36=$B$4,"ATM","") | B36: 47600 | C36: =IF(RawData!J320="","",RawData!J320) -> 14231.55 | D36: =IF(RawData!J321="","",RawData!J321) -> 0.4 | E36: =IF(OR(C36="",D36=""),"",C36+D36) -> 14231.95
A37: =IF(B37=$B$4,"ATM","") | B37: 47700 | C37: =IF(RawData!J322="","",RawData!J322) -> 14133.25 | D37: =IF(RawData!J323="","",RawData!J323) -> 0.45 | E37: =IF(OR(C37="",D37=""),"",C37+D37) -> 14133.7
A38: =IF(B38=$B$4,"ATM","") | B38: 47800 | C38: =IF(RawData!J324="","",RawData!J324) -> 14034.95 | D38: =IF(RawData!J325="","",RawData!J325) -> 0.5 | E38: =IF(OR(C38="",D38=""),"",C38+D38) -> 14035.45
A39: =IF(B39=$B$4,"ATM","") | B39: 47900 | C39: =IF(RawData!J326="","",RawData!J326) -> 13936.65 | D39: =IF(RawData!J327="","",RawData!J327) -> 0.55 | E39: =IF(OR(C39="",D39=""),"",C39+D39) -> 13937.2
A40: =IF(B40=$B$4,"ATM","") | B40: 48000 | C40: =IF(RawData!J328="","",RawData!J328) -> 6870 | D40: =IF(RawData!J329="","",RawData!J329) -> 28.85 | E40: =IF(OR(C40="",D40=""),"",C40+D40) -> 6898.85
A41: =IF(B41=$B$4,"ATM","") | B41: 48100 | C41: =IF(RawData!J330="","",RawData!J330) -> 13740.05 | D41: =IF(RawData!J331="","",RawData!J331) -> 0.65 | E41: =IF(OR(C41="",D41=""),"",C41+D41) -> 13740.7
A42: =IF(B42=$B$4,"ATM","") | B42: 48200 | C42: =IF(RawData!J332="","",RawData!J332) -> 13641.75 | D42: =IF(RawData!J333="","",RawData!J333) -> 0.75 | E42: =IF(OR(C42="",D42=""),"",C42+D42) -> 13642.5
...

Sheet SENSEX
A1: SENSEX Option Chain
A3: Nearest Expiry | B3: 46149 | D3: Spot | E3: 76984.91
A4: ATM Strike | B4: 77000 | D4: ATM Straddle | E4: 887.45
A5: Last Updated | B5: 46147.587 | D5: Status | E5: Streaming live ticks for SENSEX 2026-05-07
A7: ATM | B7: Strike | C7: Call LTP | D7: Put LTP | E7: Straddle Sum
A8: =IF(B8=$B$4,"ATM","") | B8: 64900 | C8: =IF(RawData!J705="","",RawData!J705) -> 12398.75 | D8: =IF(RawData!J706="","",RawData!J706) -> 0.7 | E8: =IF(OR(C8="",D8=""),"",C8+D8) -> 12399.45
A9: =IF(B9=$B$4,"ATM","") | B9: 65000 | C9: =IF(RawData!J707="","",RawData!J707) -> 12198 | D9: =IF(RawData!J708="","",RawData!J708) -> 0.75 | E9: =IF(OR(C9="",D9=""),"",C9+D9) -> 12198.75
A10: =IF(B10=$B$4,"ATM","") | B10: 65100 | C10: =IF(RawData!J709="","",RawData!J709) -> 12198.8 | D10: =IF(RawData!J710="","",RawData!J710) -> 1.35 | E10: =IF(OR(C10="",D10=""),"",C10+D10) -> 12200.15
A11: =IF(B11=$B$4,"ATM","") | B11: 65200 | C11: =IF(RawData!J711="","",RawData!J711) -> 12098.85 | D11: =IF(RawData!J712="","",RawData!J712) -> 1.3 | E11: =IF(OR(C11="",D11=""),"",C11+D11) -> 12100.15
A12: =IF(B12=$B$4,"ATM","") | B12: 65300 | C12: =IF(RawData!J713="","",RawData!J713) -> 11998.9 | D12: =IF(RawData!J714="","",RawData!J714) -> 0.85 | E12: =IF(OR(C12="",D12=""),"",C12+D12) -> 11999.75
A13: =IF(B13=$B$4,"ATM","") | B13: 65400 | C13: =IF(RawData!J715="","",RawData!J715) -> 11898.95 | D13: =IF(RawData!J716="","",RawData!J716) -> 0.85 | E13: =IF(OR(C13="",D13=""),"",C13+D13) -> 11899.8
A14: =IF(B14=$B$4,"ATM","") | B14: 65500 | C14: =IF(RawData!J717="","",RawData!J717) -> 11799 | D14: =IF(RawData!J718="","",RawData!J718) -> 1.05 | E14: =IF(OR(C14="",D14=""),"",C14+D14) -> 11800.05
A15: =IF(B15=$B$4,"ATM","") | B15: 65600 | C15: =IF(RawData!J719="","",RawData!J719) -> 11699.05 | D15: =IF(RawData!J720="","",RawData!J720) -> 1.95 | E15: =IF(OR(C15="",D15=""),"",C15+D15) -> 11701
A16: =IF(B16=$B$4,"ATM","") | B16: 65700 | C16: =IF(RawData!J721="","",RawData!J721) -> 11599.1 | D16: =IF(RawData!J722="","",RawData!J722) -> 1.8 | E16: =IF(OR(C16="",D16=""),"",C16+D16) -> 11600.9
A17: =IF(B17=$B$4,"ATM","") | B17: 65800 | C17: =IF(RawData!J723="","",RawData!J723) -> 11499.15 | D17: =IF(RawData!J724="","",RawData!J724) -> 1.35 | E17: =IF(OR(C17="",D17=""),"",C17+D17) -> 11500.5
A18: =IF(B18=$B$4,"ATM","") | B18: 65900 | C18: =IF(RawData!J725="","",RawData!J725) -> 11399.2 | D18: =IF(RawData!J726="","",RawData!J726) -> 1.4 | E18: =IF(OR(C18="",D18=""),"",C18+D18) -> 11400.6
A19: =IF(B19=$B$4,"ATM","") | B19: 66000 | C19: =IF(RawData!J727="","",RawData!J727) -> 11299.25 | D19: =IF(RawData!J728="","",RawData!J728) -> 1.25 | E19: =IF(OR(C19="",D19=""),"",C19+D19) -> 11300.5
A20: =IF(B20=$B$4,"ATM","") | B20: 66100 | C20: =IF(RawData!J729="","",RawData!J729) -> 11199.25 | D20: =IF(RawData!J730="","",RawData!J730) -> 1.4 | E20: =IF(OR(C20="",D20=""),"",C20+D20) -> 11200.65
A21: =IF(B21=$B$4,"ATM","") | B21: 66200 | C21: =IF(RawData!J731="","",RawData!J731) -> 11099.3 | D21: =IF(RawData!J732="","",RawData!J732) -> 1.1 | E21: =IF(OR(C21="",D21=""),"",C21+D21) -> 11100.4
A22: =IF(B22=$B$4,"ATM","") | B22: 66300 | C22: =IF(RawData!J733="","",RawData!J733) -> 10999.35 | D22: =IF(RawData!J734="","",RawData!J734) -> 1 | E22: =IF(OR(C22="",D22=""),"",C22+D22) -> 11000.35
A23: =IF(B23=$B$4,"ATM","") | B23: 66400 | C23: =IF(RawData!J735="","",RawData!J735) -> 10899.4 | D23: =IF(RawData!J736="","",RawData!J736) -> 1.15 | E23: =IF(OR(C23="",D23=""),"",C23+D23) -> 10900.55
A24: =IF(B24=$B$4,"ATM","") | B24: 66500 | C24: =IF(RawData!J737="","",RawData!J737) -> 10799.45 | D24: =IF(RawData!J738="","",RawData!J738) -> 1 | E24: =IF(OR(C24="",D24=""),"",C24+D24) -> 10800.45
A25: =IF(B25=$B$4,"ATM","") | B25: 66600 | C25: =IF(RawData!J739="","",RawData!J739) -> 10699.5 | D25: =IF(RawData!J740="","",RawData!J740) -> 1.45 | E25: =IF(OR(C25="",D25=""),"",C25+D25) -> 10700.95
A26: =IF(B26=$B$4,"ATM","") | B26: 66700 | C26: =IF(RawData!J741="","",RawData!J741) -> 10599.55 | D26: =IF(RawData!J742="","",RawData!J742) -> 1.2 | E26: =IF(OR(C26="",D26=""),"",C26+D26) -> 10600.75
A27: =IF(B27=$B$4,"ATM","") | B27: 66800 | C27: =IF(RawData!J743="","",RawData!J743) -> 10499.6 | D27: =IF(RawData!J744="","",RawData!J744) -> 1.4 | E27: =IF(OR(C27="",D27=""),"",C27+D27) -> 10501
A28: =IF(B28=$B$4,"ATM","") | B28: 66900 | C28: =IF(RawData!J745="","",RawData!J745) -> 10399.65 | D28: =IF(RawData!J746="","",RawData!J746) -> 2 | E28: =IF(OR(C28="",D28=""),"",C28+D28) -> 10401.65
A29: =IF(B29=$B$4,"ATM","") | B29: 67000 | C29: =IF(RawData!J747="","",RawData!J747) -> 10299.7 | D29: =IF(RawData!J748="","",RawData!J748) -> 1 | E29: =IF(OR(C29="",D29=""),"",C29+D29) -> 10300.7
A30: =IF(B30=$B$4,"ATM","") | B30: 67100 | C30: =IF(RawData!J749="","",RawData!J749) -> 10199.75 | D30: =IF(RawData!J750="","",RawData!J750) -> 1.85 | E30: =IF(OR(C30="",D30=""),"",C30+D30) -> 10201.6
A31: =IF(B31=$B$4,"ATM","") | B31: 67200 | C31: =IF(RawData!J751="","",RawData!J751) -> 10099.75 | D31: =IF(RawData!J752="","",RawData!J752) -> 1.4 | E31: =IF(OR(C31="",D31=""),"",C31+D31) -> 10101.15
A32: =IF(B32=$B$4,"ATM","") | B32: 67300 | C32: =IF(RawData!J753="","",RawData!J753) -> 9999.8 | D32: =IF(RawData!J754="","",RawData!J754) -> 1.15 | E32: =IF(OR(C32="",D32=""),"",C32+D32) -> 10000.95
A33: =IF(B33=$B$4,"ATM","") | B33: 67400 | C33: =IF(RawData!J755="","",RawData!J755) -> 9899.85 | D33: =IF(RawData!J756="","",RawData!J756) -> 1.45 | E33: =IF(OR(C33="",D33=""),"",C33+D33) -> 9901.3
A34: =IF(B34=$B$4,"ATM","") | B34: 67500 | C34: =IF(RawData!J757="","",RawData!J757) -> 9799.9 | D34: =IF(RawData!J758="","",RawData!J758) -> 1.1 | E34: =IF(OR(C34="",D34=""),"",C34+D34) -> 9801
A35: =IF(B35=$B$4,"ATM","") | B35: 67600 | C35: =IF(RawData!J759="","",RawData!J759) -> 9699.95 | D35: =IF(RawData!J760="","",RawData!J760) -> 1.5 | E35: =IF(OR(C35="",D35=""),"",C35+D35) -> 9701.45
A36: =IF(B36=$B$4,"ATM","") | B36: 67700 | C36: =IF(RawData!J761="","",RawData!J761) -> 9600 | D36: =IF(RawData!J762="","",RawData!J762) -> 1.7 | E36: =IF(OR(C36="",D36=""),"",C36+D36) -> 9601.7
A37: =IF(B37=$B$4,"ATM","") | B37: 67800 | C37: =IF(RawData!J763="","",RawData!J763) -> 9500.05 | D37: =IF(RawData!J764="","",RawData!J764) -> 1.25 | E37: =IF(OR(C37="",D37=""),"",C37+D37) -> 9501.3
A38: =IF(B38=$B$4,"ATM","") | B38: 67900 | C38: =IF(RawData!J765="","",RawData!J765) -> 9400.1 | D38: =IF(RawData!J766="","",RawData!J766) -> 1.35 | E38: =IF(OR(C38="",D38=""),"",C38+D38) -> 9401.45
A39: =IF(B39=$B$4,"ATM","") | B39: 68000 | C39: =IF(RawData!J767="","",RawData!J767) -> 8664.95 | D39: =IF(RawData!J768="","",RawData!J768) -> 1.2 | E39: =IF(OR(C39="",D39=""),"",C39+D39) -> 8666.15
A40: =IF(B40=$B$4,"ATM","") | B40: 68100 | C40: =IF(RawData!J769="","",RawData!J769) -> 9200.2 | D40: =IF(RawData!J770="","",RawData!J770) -> 1.75 | E40: =IF(OR(C40="",D40=""),"",C40+D40) -> 9201.95
A41: =IF(B41=$B$4,"ATM","") | B41: 68200 | C41: =IF(RawData!J771="","",RawData!J771) -> 9100.2 | D41: =IF(RawData!J772="","",RawData!J772) -> 1.35 | E41: =IF(OR(C41="",D41=""),"",C41+D41) -> 9101.55
A42: =IF(B42=$B$4,"ATM","") | B42: 68300 | C42: =IF(RawData!J773="","",RawData!J773) -> 9000.25 | D42: =IF(RawData!J774="","",RawData!J774) -> 1.55 | E42: =IF(OR(C42="",D42=""),"",C42+D42) -> 9001.8
...

Sheet RawData
A1: Index | B1: Expiry | C1: Row Type | D1: Tradingsymbol | E1: Instrument Token | F1: Exchange | G1: Segment | H1: Strike | I1: Option Type | J1: Last Price | K1: Change % | L1: Last Qty | M1: Avg Price | N1: Volume | O1: Buy Qty | P1: Sell Qty | Q1: OI | R1: OI Day High | S1: OI Day Low | T1: Open | U1: High | V1: Low | W1: Close | X1: Best Bid Price | Y1: Best Bid Qty | Z1: Best Ask Price | AA1: Best Ask Qty | AB1: Exchange Timestamp | AC1: Last Trade Time
A2: NIFTY | B2: 46147 | C2: SPOT | D2: NSE:NIFTY 50 | E2: 256265 | F2: NSE | G2: INDEX | J2: 24035.1 | K2: -0.34909803 | T2: 24052.6 | U2: 24081.7 | V2: 23882.05 | W2: 24119.3
A3: NIFTY | B3: 46147 | C3: OPTION | D3: NIFTY2650520100CE | E3: 18823682 | F3: NFO | G3: NFO-OPT | H3: 20100 | I3: CE | J3: 2979.95 | K3: 0 | L3: 0 | M3: 0 | N3: 0 | O3: 5980 | P3: 5200 | Q3: 0 | R3: 0 | S3: 0 | T3: 0 | U3: 0 | V3: 0 | W3: 2979.95 | X3: 3716.65 | Y3: 780 | Z3: 4067.35 | AA3: 130 | AB3: 46147.586 | AC3: 25569.229
A4: NIFTY | B4: 46147 | C4: OPTION | D4: NIFTY2650520100PE | E4: 18823938 | F4: NFO | G4: NFO-OPT | H4: 20100 | I4: PE | J4: 0.1 | K4: -60 | L4: 65 | M4: 0.14 | N4: 863655 | O4: 1239485 | P4: 822835 | Q4: 688870 | R4: 768690 | S4: 688870 | T4: 0.25 | U4: 0.25 | V4: 0.05 | W4: 0.25 | X4: 0.05 | Y4: 1239485 | Z4: 0.1 | AA4: 321685 | AB4: 46147.586 | AC4: 46147.586
A5: NIFTY | B5: 46147 | C5: OPTION | D5: NIFTY2650520150CE | E5: 18824194 | F5: NFO | G5: NFO-OPT | H5: 20150 | I5: CE | J5: 2930.7 | K5: 0 | L5: 0 | M5: 0 | N5: 0 | O5: 5980 | P5: 5980 | Q5: 0 | R5: 0 | S5: 0 | T5: 0 | U5: 0 | V5: 0 | W5: 2930.7 | X5: 3672 | Y5: 780 | Z5: 4017.4 | AA5: 780 | AB5: 46147.587 | AC5: 25569.229
A6: NIFTY | B6: 46147 | C6: OPTION | D6: NIFTY2650520150PE | E6: 18824450 | F6: NFO | G6: NFO-OPT | H6: 20150 | I6: PE | J6: 0.1 | K6: -66.666667 | L6: 130 | M6: 0.19 | N6: 155870 | O6: 7670 | P6: 73905 | Q6: 96070 | R6: 98150 | S6: 77740 | T6: 0.4 | U6: 0.4 | V6: 0.05 | W6: 0.3 | X6: 0.05 | Y6: 7670 | Z6: 0.1 | AA6: 13520 | AB6: 46147.587 | AC6: 46147.585
A7: NIFTY | B7: 46147 | C7: OPTION | D7: NIFTY2650520200CE | E7: 18824706 | F7: NFO | G7: NFO-OPT | H7: 20200 | I7: CE | J7: 2881.5 | K7: 0 | L7: 0 | M7: 0 | N7: 0 | O7: 5850 | P7: 5850 | Q7: 0 | R7: 0 | S7: 0 | T7: 0 | U7: 0 | V7: 0 | W7: 2881.5 | X7: 3609.05 | Y7: 780 | Z7: 3964.75 | AA7: 780 | AB7: 46147.586 | AC7: 25569.229
A8: NIFTY | B8: 46147 | C8: OPTION | D8: NIFTY2650520200PE | E8: 18824962 | F8: NFO | G8: NFO-OPT | H8: 20200 | I8: PE | J8: 0.05 | K8: -83.333333 | L8: 65 | M8: 0.17 | N8: 208520 | O8: 25480 | P8: 52715 | Q8: 69940 | R8: 73515 | S8: 57720 | T8: 0.35 | U8: 0.4 | V8: 0.05 | W8: 0.3 | X8: 0.05 | Y8: 25480 | Z8: 0.1 | AA8: 10400 | AB8: 46147.586 | AC8: 46147.585
A9: NIFTY | B9: 46147 | C9: OPTION | D9: NIFTY2650520250CE | E9: 18825218 | F9: NFO | G9: NFO-OPT | H9: 20250 | I9: CE | J9: 2832.3 | K9: 0 | L9: 0 | M9: 0 | N9: 0 | O9: 5980 | P9: 5200 | Q9: 0 | R9: 0 | S9: 0 | T9: 0 | U9: 0 | V9: 0 | W9: 2832.3 | X9: 3574.6 | Y9: 780 | Z9: 3915 | AA9: 1690 | AB9: 46147.586 | AC9: 25569.229
A10: NIFTY | B10: 46147 | C10: OPTION | D10: NIFTY2650520250PE | E10: 18825474 | F10: NFO | G10: NFO-OPT | H10: 20250 | I10: PE | J10: 0.1 | K10: -66.666667 | L10: 130 | M10: 0.23 | N10: 58175 | O10: 3510 | P10: 43030 | Q10: 33865 | R10: 41730 | S10: 33865 | T10: 0.35 | U10: 0.45 | V10: 0.05 | W10: 0.3 | X10: 0.05 | Y10: 3510 | Z10: 0.1 | AA10: 1495 | AB10: 46147.586 | AC10: 46147.585
A11: NIFTY | B11: 46147 | C11: OPTION | D11: NIFTY2650520300CE | E11: 18825730 | F11: NFO | G11: NFO-OPT | H11: 20300 | I11: CE | J11: 2783.2 | K11: 0 | L11: 0 | M11: 0 | N11: 0 | O11: 5980 | P11: 5980 | Q11: 0 | R11: 0 | S11: 0 | T11: 0 | U11: 0 | V11: 0 | W11: 2783.2 | X11: 3523.05 | Y11: 780 | Z11: 3864.25 | AA11: 780 | AB11: 46147.586 | AC11: 25569.229
A12: NIFTY | B12: 46147 | C12: OPTION | D12: NIFTY2650520300PE | E12: 18826498 | F12: NFO | G12: NFO-OPT | H12: 20300 | I12: PE | J12: 0.05 | K12: -80 | L12: 65 | M12: 0.21 | N12: 180310 | O12: 81380 | P12: 72215 | Q12: 77870 | R12: 100620 | S12: 71305 | T12: 0.4 | U12: 0.65 | V12: 0.05 | W12: 0.25 | X12: 0.05 | Y12: 81380 | Z12: 0.1 | AA12: 5785 | AB12: 46147.586 | AC12: 46147.585
A13: NIFTY | B13: 46147 | C13: OPTION | D13: NIFTY2650520350CE | E13: 18826754 | F13: NFO | G13: NFO-OPT | H13: 20350 | I13: CE | J13: 2734.15 | K13: 0 | L13: 0 | M13: 0 | N13: 0 | O13: 5980 | P13: 5980 | Q13: 0 | R13: 0 | S13: 0 | T13: 0 | U13: 0 | V13: 0 | W13: 2734.15 | X13: 3449.25 | Y13: 780 | Z13: 3814.8 | AA13: 780 | AB13: 46147.587 | AC13: 25569.229
A14: NIFTY | B14: 46147 | C14: OPTION | D14: NIFTY2650520350PE | E14: 18833666 | F14: NFO | G14: NFO-OPT | H14: 20350 | I14: PE | J14: 0.1 | K14: -66.666667 | L14: 715 | M14: 0.26 | N14: 87230 | O14: 11505 | P14: 46995 | Q14: 41470 | R14: 50570 | S14: 39585 | T14: 1 | U14: 1 | V14: 0.1 | W14: 0.3 | X14: 0.1 | Y14: 8060 | Z14: 0.15 | AA14: 1040 | AB14: 46147.587 | AC14: 46147.584
... A262: NIFTY | B262: 46147 | C262: OPTION | D262: NIFTY2650526550PE | E262: 19094274 | F262: NFO | G262: NFO-OPT | H262: 26550 | I262: PE | J262: 3421.65 | K262: 0 | L262: 0 | M262: 0 | N262: 0 | O262: 1300 | P262: 5980 | Q262: 0 | R262: 0 | S262: 0 | T262: 0 | U262: 0 | V262: 0 | W262: 3421.65 | X262: 2276.4 | Y262: 780 | Z262: 2572.2 | AA262: 780 | AB262: 46147.586 | AC262: 25569.229
A263: BANKNIFTY | B263: 46168 | C263: SPOT | D263: NSE:NIFTY BANK | E263: 260105 | F263: NSE | G263: INDEX | J263: 54740.6 | K263: -0.25128238 | T263: 54691.3 | U263: 54888.55 | V263: 54221.65 | W263: 54878.5
A264: BANKNIFTY | B264: 46168 | C264: OPTION | D264: BANKNIFTY26MAY43000CE | E264: 17013250 | F264: NFO | G264: NFO-OPT | H264: 43000 | I264: CE | J264: 8000 | K264: 0 | L264: 30 | M264: 0 | N264: 0 | O264: 4830 | P264: 4830 | Q264: 30 | R264: 30 | S264: 30 | T264: 0 | U264: 0 | V264: 0 | W264: 8000 | X264: 11214.8 | Y264: 300 | Z264: 12430.6 | AA264: 300 | AB264: 46147.586 | AC264: 46114.398
A265: BANKNIFTY | B265: 46168 | C265: OPTION | D265: BANKNIFTY26MAY43000PE | E265: 17013506 | F265: NFO | G265: NFO-OPT | H265: 43000 | I265: PE | J265: 7.05 | K265: 0 | L265: 120 | M265: 7.53 | N265: 53820 | O265: 151710 | P265: 31680 | Q265: 89490 | R265: 97470 | S265: 86970 | T265: 6.55 | U265: 8.8 | V265: 6.25 | W265: 7.05 | X265: 7.05 | Y265: 90 | Z265: 7.25 | AA265: 150 | AB265: 46147.586 | AC265: 46147.578
A266: BANKNIFTY | B266: 46168 | C266: OPTION | D266: BANKNIFTY26MAY43500CE | E266: 17013762 | F266: NFO | G266: NFO-OPT | H266: 43500 | I266: CE | J266: 18263.65 | K266: 0 | L266: 0 | M266: 0 | N266: 0 | O266: 4410 | P266: 4410 | Q266: 0 | R266: 0 | S266: 0 | T266: 0 | U266: 0 | V266: 0 | W266: 18263.65 | X266: 10266.8 | Y266: 300 | Z266: 12175.55 | AA266: 300 | AB266: 46147.586 | AC266: 25569.229
A267: BANKNIFTY | B267: 46168 | C267: OPTION | D267: BANKNIFTY26MAY43500PE | E267: 17014018 | F267: NFO | G267: NFO-OPT | H267: 43500 | I267: PE | J267: 6.8 | K267: -7.4829932 | L267: 30 | M267: 7.14 | N267: 15990 | O267: 119700 | P267: 17880 | Q267: 20340 | R267: 20580 | S267: 20190 | T267: 7.1 | U267: 8.6 | V267: 5.85 | W267: 7.35 | X267: 6.8 | Y267: 30 | Z267: 6.95 | AA267: 30 | AB267: 46147.586 | AC267: 46147.584
A268: BANKNIFTY | B268: 46168 | C268: OPTION | D268: BANKNIFTY26MAY44000CE | E268: 17014274 | F268: NFO | G268: NFO-OPT | H268: 44000 | I268: CE | J268: 12162 | K268: 0 | L268: 30 | M268: 0 | N268: 0 | O268: 4830 | P268: 4470 | Q268: 1290 | R268: 1290 | S268: 1290 | T268: 0 | U268: 0 | V268: 0 | W268: 12162 | X268: 10148.45 | Y268: 300 | Z268: 11417.3 | AA268: 300 | AB268: 46147.586 | AC268: 46141.436
A269: BANKNIFTY | B269: 46168 | C269: OPTION | D269: BANKNIFTY26MAY44000PE | E269: 17014530 | F269: NFO | G269: NFO-OPT | H269: 44000 | I269: PE | J269: 7.65 | K269: -4.9689441 | L269: 90 | M269: 8.38 | N269: 20700 | O269: 118560 | P269: 19770 | Q269: 89910 | R269: 89940 | S269: 86520 | T269: 7.25 | U269: 10.25 | V269: 7.1 | W269: 8.05 | X269: 7.65 | Y269: 150 | Z269: 8.15 | AA269: 90 | AB269: 46147.586 | AC269: 46147.582
A270: BANKNIFTY | B270: 46168 | C270: OPTION | D270: BANKNIFTY26MAY44500CE | E270: 17014786 | F270: NFO | G270: NFO-OPT | H270: 44500 | I270: CE | J270: 17280.1 | K270: 0 | L270: 0 | M270: 0 | N270: 0 | O270: 3510 | P270: 3210 | Q270: 0 | R270: 0 | S270: 0 | T270: 0 | U270: 0 | V270: 0 | W270: 17280.1 | X270: 9357.3 | Y270: 300 | Z270: 11023.8 | AA270: 870 | AB270: 46147.586 | AC270: 25569.229
A271: BANKNIFTY | B271: 46168 | C271: OPTION | D271: BANKNIFTY26MAY44500PE | E271: 17015042 | F271: NFO | G271: NFO-OPT | H271: 44500 | I271: PE | J271: 8.3 | K271: -2.9239766 | L271: 90 | M271: 8.72 | N271: 2370 | O271: 104610 | P271: 18360 | Q271: 6750 | R271: 6810 | S271: 6630 | T271: 8 | U271: 9.5 | V271: 8 | W271: 8.55 | X271: 7.85 | Y271: 120 | Z271: 8.3 | AA271: 60 | AB271: 46147.586 | AC271: 46147.584
A272: BANKNIFTY | B272: 46168 | C272: OPTION | D272: BANKNIFTY26MAY45000CE | E272: 17015298 | F272: NFO | G272: NFO-OPT | H272: 45000 | I272: CE | J272: 16788.35 | K272: 0 | L272: 0 | M272: 0 | N272: 0 | O272: 4410 | P272: 4410 | Q272: 0 | R272: 0 | S272: 0 | T272: 0 | U272: 0 | V272: 0 | W272: 16788.35 | X272: 8902.55 | Y272: 1170 | Z272: 10279.7 | AA272: 300 | AB272: 46147.586 | AC272: 25569.229
A273: BANKNIFTY | B273: 46168 | C273: OPTION | D273: BANKNIFTY26MAY45000PE | E273: 17015554 | F273: NFO | G273: NFO-OPT | H273: 45000 | I273: PE | J273: 8.75 | K273: -1.6853933 | L273: 30 | M273: 9.11 | N273: 44220 | O273: 111120 | P273: 19170 | Q273: 105630 | R273: 105660 | S273: 103830 | T273: 9.05 | U273: 11 | V273: 8.1 | W273: 8.9 | X273: 8.7 | Y273: 30 | Z273: 8.75 | AA273: 60 | AB273: 46147.586 | AC273: 46147.585
A274: BANKNIFTY | B274: 46168 | C274: OPTION | D274: BANKNIFTY26MAY45300CE | E274: 10340866 | F274: NFO | G274: NFO-OPT | H274: 45300 | I274: CE | J274: 15239 | K274: 0 | L274: 0 | M274: 0 | N274: 0 | O274: 2970 | P274: 2970 | Q274: 0 | R274: 0 | S274: 0 | T274: 0 | U274: 0 | V274: 0 | W274: 15239 | X274: 8643.9 | Y274: 300 | Z274: 10342.2 | AA274: 300 | AB274: 46147.586 | AC274: 25569.229
A275: BANKNIFTY | B275: 46168 | C275: OPTION | D275: BANKNIFTY26MAY45300PE | E275: 10341122 | F275: NFO | G275: NFO-OPT | H275: 45300 | I275: PE | J275: 11.05 | K275: 16.931217 | L275: 30 | M275: 10.58 | N275: 3900 | O275: 28740 | P275: 4950 | Q275: 2880 | R275: 2910 | S275: 870 | T275: 9 | U275: 12.5 | V275: 7.7 | W275: 9.45 | X275: 9.55 | Y275: 210 | Z275: 11.85 | AA275: 30 | AB275: 46147.585 | AC275: 46147.573
... A703: BANKNIFTY | B703: 46168 | C703: OPTION | D703: BANKNIFTY26MAY68500PE | E703: 17522178 | F703: NFO | G703: NFO-OPT | H703: 68500 | I703: PE | J703: 10900 | K703: 0 | L703: 30 | M703: 0 | N703: 0 | O703: 4830 | P703: 4830 | Q703: 150 | R703: 150 | S703: 150 | T703: 0 | U703: 0 | V703: 0 | W703: 10900 | X703: 12191.2 | Y703: 300 | Z703: 14324.2 | AA703: 300 | AB703: 46147.586 | AC703: 46134.438
A704: SENSEX | B704: 46149 | C704: SPOT | D704: BSE:SENSEX | E704: 265 | F704: BSE | G704: INDEX | J704: 76996.33 | K704: -0.35339992 | T704: 77103.72 | U704: 77151.33 | V704: 76515.03 | W704: 77269.4
A705: SENSEX | B705: 46149 | C705: OPTION | D705: SENSEX2650764900CE | E705: 286274053 | F705: BFO | G705: BFO-OPT | H705: 64900 | I705: CE | J705: 12398.75 | K705: 0 | L705: 0 | M705: 0 | N705: 0 | O705: 100 | P705: 100 | Q705: 0 | R705: 0 | S705: 0 | T705: 0 | U705: 0 | V705: 0 | W705: 12398.75 | X705: 10500 | Y705: 100 | Z705: 13500 | AA705: 100 | AB705: 46147.586 | AC705: 25569.229
A706: SENSEX | B706: 46149 | C706: OPTION | D706: SENSEX2650764900PE | E706: 286482949 | F706: BFO | G706: BFO-OPT | H706: 64900 | I706: PE | J706: 0.7 | K706: -68.888889 | L706: 100 | M706: 1.52 | N706: 17040 | O706: 47040 | P706: 13680 | Q706: 13180 | R706: 15020 | S706: 13080 | T706: 1.65 | U706: 2.4 | V706: 0.7 | W706: 2.25 | X706: 0.7 | Y706: 1900 | Z706: 0.9 | AA706: 240 | AB706: 46147.587 | AC706: 46147.585
A707: SENSEX | B707: 46149 | C707: OPTION | D707: SENSEX2650765000CE | E707: 286883333 | F707: BFO | G707: BFO-OPT | H707: 65000 | I707: CE | J707: 12198 | K707: -0.81959216 | L707: 20 | M707: 12198 | N707: 20 | O707: 460 | P707: 460 | Q707: 20 | R707: 20 | S707: 20 | T707: 12198 | U707: 12198 | V707: 12198 | W707: 12298.8 | X707: 11955.85 | Y707: 20 | Z707: 12167.35 | AA707: 20 | AB707: 46147.586 | AC707: 46147.44
A708: SENSEX | B708: 46149 | C708: OPTION | D708: SENSEX2650765000PE | E708: 287083269 | F708: BFO | G708: BFO-OPT | H708: 65000 | I708: PE | J708: 0.75 | K708: -64.285714 | L708: 40 | M708: 1.35 | N708: 56060 | O708: 89720 | P708: 14960 | Q708: 28080 | R708: 33280 | S708: 27920 | T708: 1.95 | U708: 2.3 | V708: 0.75 | W708: 2.1 | X708: 0.75 | Y708: 2060 | Z708: 0.85 | AA708: 140 | AB708: 46147.586 | AC708: 46147.585
A709: SENSEX | B709: 46149 | C709: OPTION | D709: SENSEX2650765100CE | E709: 286068485 | F709: BFO | G709: BFO-OPT | H709: 65100 | I709: CE | J709: 12198.8 | K709: 0 | L709: 0 | M709: 0 | N709: 0 | O709: 100 | P709: 100 | Q709: 0 | R709: 0 | S709: 0 | T709: 0 | U709: 0 | V709: 0 | W709: 12198.8 | X709: 10300 | Y709: 100 | Z709: 13300 | AA709: 100 | AB709: 46147.586 | AC709: 25569.229
A710: SENSEX | B710: 46149 | C710: OPTION | D710: SENSEX2650765100PE | E710: 286850565 | F710: BFO | G710: BFO-OPT | H710: 65100 | I710: PE | J710: 1.35 | K710: -34.146341 | L710: 20 | M710: 1.78 | N710: 28000 | O710: 56760 | P710: 9040 | Q710: 15640 | R710: 19040 | S710: 9000 | T710: 2 | U710: 2.6 | V710: 0.7 | W710: 2.05 | X710: 0.9 | Y710: 20 | Z710: 1.05 | AA710: 300 | AB710: 46147.587 | AC710: 46147.583
A711: SENSEX | B711: 46149 | C711: OPTION | D711: SENSEX2650765200CE | E711: 286948357 | F711: BFO | G711: BFO-OPT | H711: 65200 | I711: CE | J711: 12098.85 | K711: 0 | L711: 0 | M711: 0 | N711: 0 | O711: 100 | P711: 100 | Q711: 0 | R711: 0 | S711: 0 | T711: 0 | U711: 0 | V711: 0 | W711: 12098.85 | X711: 10200 | Y711: 100 | Z711: 13200 | AA711: 100 | AB711: 46147.586 | AC711: 25569.229
A712: SENSEX | B712: 46149 | C712: OPTION | D712: SENSEX2650765200PE | E712: 286011397 | F712: BFO | G712: BFO-OPT | H712: 65200 | I712: PE | J712: 1.3 | K712: -35 | L712: 20 | M712: 1.98 | N712: 3200 | O712: 45040 | P712: 6880 | Q712: 1160 | R712: 1460 | S712: 760 | T712: 2.95 | U712: 2.95 | V712: 0.8 | W712: 2 | X712: 0.65 | Y712: 2000 | Z712: 1.1 | AA712: 80 | AB712: 46147.587 | AC712: 46147.583
A713: SENSEX | B713: 46149 | C713: OPTION | D713: SENSEX2650765300CE | E713: 286196229 | F713: BFO | G713: BFO-OPT | H713: 65300 | I713: CE | J713: 11998.9 | K713: 0 | L713: 0 | M713: 0 | N713: 0 | O713: 100 | P713: 100 | Q713: 0 | R713: 0 | S713: 0 | T713: 0 | U713: 0 | V713: 0 | W713: 11998.9 | X713: 10100 | Y713: 100 | Z713: 13100 | AA713: 100 | AB713: 46147.586 | AC713: 25569.229
A714: SENSEX | B714: 46149 | C714: OPTION | D714: SENSEX2650765300PE | E714: 286914053 | F714: BFO | G714: BFO-OPT | H714: 65300 | I714: PE | J714: 0.85 | K714: -51.428571 | L714: 20 | M714: 1.81 | N714: 2700 | O714: 36520 | P714: 7960 | Q714: 1800 | R714: 1940 | S714: 1500 | T714: 2.3 | U714: 2.85 | V714: 0.85 | W714: 1.75 | X714: 0.85 | Y714: 3500 | Z714: 1.5 | AA714: 100 | AB714: 46147.587 | AC714: 46147.583
...

Sheet Meta
A1: simple-option-chain-v2
